[32mINFO    [0m pytest_operator.plugin:plugin.py:790 Model status:

Model  Controller          Cloud/Region        Version  SLA          Timestamp
test   microk8s-localhost  microk8s/localhost  3.1.7    unsupported  01:46:32Z

App             Version                  Status  Scale  Charm           Channel      Rev  Address         Exposed  Message
mysql-k8s       8.0.35-0ubuntu0.22.04.1  active      3  mysql-k8s                      0  10.152.183.61   no       
mysql-test-app  0.0.2                    active      1  mysql-test-app  latest/edge   33  10.152.183.182  no       Last written value=43567

Unit               Workload  Agent  Address      Ports  Message
mysql-k8s/0        active    idle   10.1.196.11         
mysql-k8s/1        active    idle   10.1.196.13         
mysql-k8s/2*       active    idle   10.1.196.12         Primary
mysql-test-app/0*  active    idle   10.1.196.14         Last written value=43567

[32mINFO    [0m pytest_operator.plugin:plugin.py:796 Juju error logs:

unit-mysql-k8s-0: 01:31:48 ERROR unit.mysql-k8s/0.juju-log Failed to get cluster status for test_cluster
unit-mysql-k8s-0: 01:33:25 ERROR unit.mysql-k8s/0.juju-log Failed to get cluster status for test_cluster
unit-mysql-k8s-0: 01:37:35 ERROR unit.mysql-k8s/0.juju-log Failed to get cluster status for test_cluster
unit-mysql-k8s-1: 01:37:59 ERROR juju.worker.dependency "api-caller" manifold worker returned unexpected error: api connection broken unexpectedly
unit-mysql-k8s-1: 01:37:59 ERROR juju.worker.caasunitterminationworker error while terminating unit: connection is shut down
unit-mysql-k8s-1: 01:38:05 ERROR juju.worker.dependency "api-caller" manifold worker returned unexpected error: [c7decd] "unit-mysql-k8s-1" cannot open api: cannot resolve "controller-service.controller-microk8s-localhost.svc.cluster.local": lookup controller-service.controller-microk8s-localhost.svc.cluster.local: i/o timeout
unit-mysql-k8s-1: 01:38:11 ERROR juju.worker.dependency "api-caller" manifold worker returned unexpected error: [c7decd] "unit-mysql-k8s-1" cannot open api: cannot resolve "controller-service.controller-microk8s-localhost.svc.cluster.local": lookup controller-service.controller-microk8s-localhost.svc.cluster.local: i/o timeout
unit-mysql-k8s-1: 01:38:19 ERROR juju.worker.dependency "api-caller" manifold worker returned unexpected error: [c7decd] "unit-mysql-k8s-1" cannot open api: cannot resolve "controller-service.controller-microk8s-localhost.svc.cluster.local": lookup controller-service.controller-microk8s-localhost.svc.cluster.local: i/o timeout
unit-mysql-k8s-1: 01:38:27 ERROR juju.worker.dependency "api-caller" manifold worker returned unexpected error: [c7decd] "unit-mysql-k8s-1" cannot open api: cannot resolve "controller-service.controller-microk8s-localhost.svc.cluster.local": lookup controller-service.controller-microk8s-localhost.svc.cluster.local: i/o timeout
unit-mysql-k8s-1: 01:38:36 ERROR juju.worker.dependency "api-caller" manifold worker returned unexpected error: [c7decd] "unit-mysql-k8s-1" cannot open api: cannot resolve "controller-service.controller-microk8s-localhost.svc.cluster.local": lookup controller-service.controller-microk8s-localhost.svc.cluster.local: i/o timeout
unit-mysql-k8s-1: 01:38:48 ERROR juju.worker.dependency "api-caller" manifold worker returned unexpected error: [c7decd] "unit-mysql-k8s-1" cannot open api: cannot resolve "controller-service.controller-microk8s-localhost.svc.cluster.local": lookup controller-service.controller-microk8s-localhost.svc.cluster.local: i/o timeout
unit-mysql-k8s-1: 01:41:01 ERROR unit.mysql-k8s/1.juju-log Failed to flush [<MySQLTextLogs.ERROR: 'ERROR LOGS'>, <MySQLTextLogs.GENERAL: 'GENERAL LOGS'>, <MySQLTextLogs.SLOW: 'SLOW LOGS'>] logs.
Traceback (most recent call last):
  File "/var/lib/juju/agents/unit-mysql-k8s-1/charm/src/mysql_k8s_helpers.py", line 666, in _run_mysqlsh_script
    stdout, _ = process.wait_output()
  File "/var/lib/juju/agents/unit-mysql-k8s-1/charm/venv/ops/pebble.py", line 1540, in wait_output
    raise ExecError[AnyStr](self._command, exit_code, out_value, err_value)
ops.pebble.ExecError: non-zero exit code 1 executing ['/usr/bin/mysqlsh', '--no-wizard', '--python', '--verbose=1', '-f', '/tmp/script.py', ';', 'rm', '/tmp/script.py'], stdout='', stderr='Cannot set LC_ALL to locale en_US.UTF-8: No such file or directory\nverbose: 2024-03-10T01:41:01Z: Loading startup files...\nverbose: 2024-03-10T01:41:01Z: Loading plugins...\nverbose: 2024-03-10T01:41:01Z: Connecting to MySQL at: serverconfig@mysql-k8s-1.mysql-k8s-endpoints.test.svc.cluster.local\nTraceback (most recent call last):\n  File "<string>", line 1, in <module>\nmysqlsh.DBError: MySQL Error (2003): Shell.connect: Can\'t connect to MySQL server on \'mysql-k8s-1.mysql-k8s-endpoints.test.svc.cluster.local:3306\' (111)\n'

During handling of the above exception, another exception occurred:

Traceback (most recent call last):
  File "/var/lib/juju/agents/unit-mysql-k8s-1/charm/lib/charms/mysql/v0/mysql.py", line 2532, in flush_mysql_logs
    self._run_mysqlsh_script("\n".join(flush_logs_commands))
  File "/var/lib/juju/agents/unit-mysql-k8s-1/charm/src/mysql_k8s_helpers.py", line 669, in _run_mysqlsh_script
    raise MySQLClientError(e.stderr)
charms.mysql.v0.mysql.MySQLClientError: Cannot set LC_ALL to locale en_US.UTF-8: No such file or directory
verbose: 2024-03-10T01:41:01Z: Loading startup files...
verbose: 2024-03-10T01:41:01Z: Loading plugins...
verbose: 2024-03-10T01:41:01Z: Connecting to MySQL at: serverconfig@mysql-k8s-1.mysql-k8s-endpoints.test.svc.cluster.local
Traceback (most recent call last):
  File "<string>", line 1, in <module>
mysqlsh.DBError: MySQL Error (2003): Shell.connect: Can't connect to MySQL server on 'mysql-k8s-1.mysql-k8s-endpoints.test.svc.cluster.local:3306' (111)

unit-mysql-k8s-0: 01:41:01 ERROR unit.mysql-k8s/0.juju-log Failed to flush [<MySQLTextLogs.ERROR: 'ERROR LOGS'>, <MySQLTextLogs.GENERAL: 'GENERAL LOGS'>, <MySQLTextLogs.SLOW: 'SLOW LOGS'>] logs.
Traceback (most recent call last):
  File "/var/lib/juju/agents/unit-mysql-k8s-0/charm/src/mysql_k8s_helpers.py", line 666, in _run_mysqlsh_script
    stdout, _ = process.wait_output()
  File "/var/lib/juju/agents/unit-mysql-k8s-0/charm/venv/ops/pebble.py", line 1540, in wait_output
    raise ExecError[AnyStr](self._command, exit_code, out_value, err_value)
ops.pebble.ExecError: non-zero exit code 1 executing ['/usr/bin/mysqlsh', '--no-wizard', '--python', '--verbose=1', '-f', '/tmp/script.py', ';', 'rm', '/tmp/script.py'], stdout='', stderr='Cannot set LC_ALL to locale en_US.UTF-8: No such file or directory\nverbose: 2024-03-10T01:41:01Z: Loading startup files...\nverbose: 2024-03-10T01:41:01Z: Loading plugins...\nverbose: 2024-03-10T01:41:01Z: Connecting to MySQL at: serverconfig@mysql-k8s-0.mysql-k8s-endpoints.test.svc.cluster.local\nTraceback (most recent call last):\n  File "<string>", line 1, in <module>\nmysqlsh.DBError: MySQL Error (2003): Shell.connect: Can\'t connect to MySQL server on \'mysql-k8s-0.mysql-k8s-endpoints.test.svc.cluster.local:3306\' (111)\n'

During handling of the above exception, another exception occurred:

Traceback (most recent call last):
  File "/var/lib/juju/agents/unit-mysql-k8s-0/charm/lib/charms/mysql/v0/mysql.py", line 2532, in flush_mysql_logs
    self._run_mysqlsh_script("\n".join(flush_logs_commands))
  File "/var/lib/juju/agents/unit-mysql-k8s-0/charm/src/mysql_k8s_helpers.py", line 669, in _run_mysqlsh_script
    raise MySQLClientError(e.stderr)
charms.mysql.v0.mysql.MySQLClientError: Cannot set LC_ALL to locale en_US.UTF-8: No such file or directory
verbose: 2024-03-10T01:41:01Z: Loading startup files...
verbose: 2024-03-10T01:41:01Z: Loading plugins...
verbose: 2024-03-10T01:41:01Z: Connecting to MySQL at: serverconfig@mysql-k8s-0.mysql-k8s-endpoints.test.svc.cluster.local
Traceback (most recent call last):
  File "<string>", line 1, in <module>
mysqlsh.DBError: MySQL Error (2003): Shell.connect: Can't connect to MySQL server on 'mysql-k8s-0.mysql-k8s-endpoints.test.svc.cluster.local:3306' (111)

unit-mysql-k8s-2: 01:41:04 ERROR unit.mysql-k8s/2.juju-log Failed to flush [<MySQLTextLogs.ERROR: 'ERROR LOGS'>, <MySQLTextLogs.GENERAL: 'GENERAL LOGS'>, <MySQLTextLogs.SLOW: 'SLOW LOGS'>] logs.
Traceback (most recent call last):
  File "/var/lib/juju/agents/unit-mysql-k8s-2/charm/src/mysql_k8s_helpers.py", line 666, in _run_mysqlsh_script
    stdout, _ = process.wait_output()
  File "/var/lib/juju/agents/unit-mysql-k8s-2/charm/venv/ops/pebble.py", line 1540, in wait_output
    raise ExecError[AnyStr](self._command, exit_code, out_value, err_value)
ops.pebble.ExecError: non-zero exit code 1 executing ['/usr/bin/mysqlsh', '--no-wizard', '--python', '--verbose=1', '-f', '/tmp/script.py', ';', 'rm', '/tmp/script.py'], stdout='', stderr='Cannot set LC_ALL to locale en_US.UTF-8: No such file or directory\nverbose: 2024-03-10T01:41:01Z: Loading startup files...\nverbose: 2024-03-10T01:41:01Z: Loading plugins...\nverbose: 2024-03-10T01:41:01Z: Connecting to MySQL at: serverconfig@mysql-k8s-2.mysql-k8s-endpoints.test.svc.cluster.local\nTraceback (most recent call last):\n  File "<string>", line 1, in <module>\nmysqlsh.DBError: MySQL Error (2013): Shell.connect: Lost connection to MySQL server at \'reading initial communication packet\', system error: 104\n'

During handling of the above exception, another exception occurred:

Traceback (most recent call last):
  File "/var/lib/juju/agents/unit-mysql-k8s-2/charm/lib/charms/mysql/v0/mysql.py", line 2532, in flush_mysql_logs
    self._run_mysqlsh_script("\n".join(flush_logs_commands))
  File "/var/lib/juju/agents/unit-mysql-k8s-2/charm/src/mysql_k8s_helpers.py", line 669, in _run_mysqlsh_script
    raise MySQLClientError(e.stderr)
charms.mysql.v0.mysql.MySQLClientError: Cannot set LC_ALL to locale en_US.UTF-8: No such file or directory
verbose: 2024-03-10T01:41:01Z: Loading startup files...
verbose: 2024-03-10T01:41:01Z: Loading plugins...
verbose: 2024-03-10T01:41:01Z: Connecting to MySQL at: serverconfig@mysql-k8s-2.mysql-k8s-endpoints.test.svc.cluster.local
Traceback (most recent call last):
  File "<string>", line 1, in <module>
mysqlsh.DBError: MySQL Error (2013): Shell.connect: Lost connection to MySQL server at 'reading initial communication packet', system error: 104

unit-mysql-k8s-0: 01:42:06 ERROR unit.mysql-k8s/0.juju-log Failed to get cluster status for test_cluster
unit-mysql-k8s-0: 01:42:06 ERROR unit.mysql-k8s/0.juju-log Failed to get cluster endpoints
Traceback (most recent call last):
  File "/var/lib/juju/agents/unit-mysql-k8s-0/charm/src/mysql_k8s_helpers.py", line 836, in update_endpoints
    rw_endpoints, ro_endpoints, offline = self.get_cluster_endpoints(get_ips=False)
  File "/var/lib/juju/agents/unit-mysql-k8s-0/charm/lib/charms/mysql/v0/mysql.py", line 1469, in get_cluster_endpoints
    raise MySQLGetClusterEndpointsError("Failed to get endpoints from cluster status")
charms.mysql.v0.mysql.MySQLGetClusterEndpointsError: Failed to get endpoints from cluster status
unit-mysql-k8s-2: 01:42:06 ERROR unit.mysql-k8s/2.juju-log Failed to get cluster status for test_cluster
unit-mysql-k8s-2: 01:42:06 ERROR unit.mysql-k8s/2.juju-log Failed to get cluster endpoints
Traceback (most recent call last):
  File "/var/lib/juju/agents/unit-mysql-k8s-2/charm/src/mysql_k8s_helpers.py", line 836, in update_endpoints
    rw_endpoints, ro_endpoints, offline = self.get_cluster_endpoints(get_ips=False)
  File "/var/lib/juju/agents/unit-mysql-k8s-2/charm/lib/charms/mysql/v0/mysql.py", line 1469, in get_cluster_endpoints
    raise MySQLGetClusterEndpointsError("Failed to get endpoints from cluster status")
charms.mysql.v0.mysql.MySQLGetClusterEndpointsError: Failed to get endpoints from cluster status
unit-mysql-k8s-2: 01:42:07 ERROR unit.mysql-k8s/2.juju-log database-peers:2: Failed to get cluster status for test_cluster
unit-mysql-k8s-2: 01:42:07 ERROR unit.mysql-k8s/2.juju-log database-peers:2: Failed to get cluster endpoints
Traceback (most recent call last):
  File "/var/lib/juju/agents/unit-mysql-k8s-2/charm/src/mysql_k8s_helpers.py", line 836, in update_endpoints
    rw_endpoints, ro_endpoints, offline = self.get_cluster_endpoints(get_ips=False)
  File "/var/lib/juju/agents/unit-mysql-k8s-2/charm/lib/charms/mysql/v0/mysql.py", line 1469, in get_cluster_endpoints
    raise MySQLGetClusterEndpointsError("Failed to get endpoints from cluster status")
charms.mysql.v0.mysql.MySQLGetClusterEndpointsError: Failed to get endpoints from cluster status
unit-mysql-k8s-0: 01:42:07 ERROR unit.mysql-k8s/0.juju-log database-peers:2: Failed to get cluster status for test_cluster
unit-mysql-k8s-0: 01:42:07 ERROR unit.mysql-k8s/0.juju-log database-peers:2: Failed to get cluster endpoints
Traceback (most recent call last):
  File "/var/lib/juju/agents/unit-mysql-k8s-0/charm/src/mysql_k8s_helpers.py", line 836, in update_endpoints
    rw_endpoints, ro_endpoints, offline = self.get_cluster_endpoints(get_ips=False)
  File "/var/lib/juju/agents/unit-mysql-k8s-0/charm/lib/charms/mysql/v0/mysql.py", line 1469, in get_cluster_endpoints
    raise MySQLGetClusterEndpointsError("Failed to get endpoints from cluster status")
charms.mysql.v0.mysql.MySQLGetClusterEndpointsError: Failed to get endpoints from cluster status
unit-mysql-k8s-1: 01:42:07 ERROR unit.mysql-k8s/1.juju-log database-peers:2: Failed to get cluster status for test_cluster
unit-mysql-k8s-1: 01:42:07 ERROR unit.mysql-k8s/1.juju-log database-peers:2: Failed to get cluster endpoints
Traceback (most recent call last):
  File "/var/lib/juju/agents/unit-mysql-k8s-1/charm/src/mysql_k8s_helpers.py", line 836, in update_endpoints
    rw_endpoints, ro_endpoints, offline = self.get_cluster_endpoints(get_ips=False)
  File "/var/lib/juju/agents/unit-mysql-k8s-1/charm/lib/charms/mysql/v0/mysql.py", line 1469, in get_cluster_endpoints
    raise MySQLGetClusterEndpointsError("Failed to get endpoints from cluster status")
charms.mysql.v0.mysql.MySQLGetClusterEndpointsError: Failed to get endpoints from cluster status
unit-mysql-k8s-1: 01:42:09 ERROR unit.mysql-k8s/1.juju-log database-peers:2: Failed to get cluster status for test_cluster
unit-mysql-k8s-1: 01:42:09 ERROR unit.mysql-k8s/1.juju-log database-peers:2: Failed to get cluster endpoints
Traceback (most recent call last):
  File "/var/lib/juju/agents/unit-mysql-k8s-1/charm/src/mysql_k8s_helpers.py", line 836, in update_endpoints
    rw_endpoints, ro_endpoints, offline = self.get_cluster_endpoints(get_ips=False)
  File "/var/lib/juju/agents/unit-mysql-k8s-1/charm/lib/charms/mysql/v0/mysql.py", line 1469, in get_cluster_endpoints
    raise MySQLGetClusterEndpointsError("Failed to get endpoints from cluster status")
charms.mysql.v0.mysql.MySQLGetClusterEndpointsError: Failed to get endpoints from cluster status
unit-mysql-k8s-1: 01:42:13 ERROR unit.mysql-k8s/1.juju-log Failed to get cluster status for test_cluster
unit-mysql-k8s-1: 01:42:13 ERROR unit.mysql-k8s/1.juju-log Failed to get cluster endpoints
Traceback (most recent call last):
  File "/var/lib/juju/agents/unit-mysql-k8s-1/charm/src/mysql_k8s_helpers.py", line 836, in update_endpoints
    rw_endpoints, ro_endpoints, offline = self.get_cluster_endpoints(get_ips=False)
  File "/var/lib/juju/agents/unit-mysql-k8s-1/charm/lib/charms/mysql/v0/mysql.py", line 1469, in get_cluster_endpoints
    raise MySQLGetClusterEndpointsError("Failed to get endpoints from cluster status")
charms.mysql.v0.mysql.MySQLGetClusterEndpointsError: Failed to get endpoints from cluster status
unit-mysql-k8s-0: 01:42:14 ERROR unit.mysql-k8s/0.juju-log database-peers:2: Failed to get cluster status for test_cluster
unit-mysql-k8s-0: 01:42:14 ERROR unit.mysql-k8s/0.juju-log database-peers:2: Failed to get cluster endpoints
Traceback (most recent call last):
  File "/var/lib/juju/agents/unit-mysql-k8s-0/charm/src/mysql_k8s_helpers.py", line 836, in update_endpoints
    rw_endpoints, ro_endpoints, offline = self.get_cluster_endpoints(get_ips=False)
  File "/var/lib/juju/agents/unit-mysql-k8s-0/charm/lib/charms/mysql/v0/mysql.py", line 1469, in get_cluster_endpoints
    raise MySQLGetClusterEndpointsError("Failed to get endpoints from cluster status")
charms.mysql.v0.mysql.MySQLGetClusterEndpointsError: Failed to get endpoints from cluster status
unit-mysql-k8s-2: 01:42:14 ERROR unit.mysql-k8s/2.juju-log database-peers:2: Failed to get cluster status for test_cluster
unit-mysql-k8s-2: 01:42:14 ERROR unit.mysql-k8s/2.juju-log database-peers:2: Failed to get cluster endpoints
Traceback (most recent call last):
  File "/var/lib/juju/agents/unit-mysql-k8s-2/charm/src/mysql_k8s_helpers.py", line 836, in update_endpoints
    rw_endpoints, ro_endpoints, offline = self.get_cluster_endpoints(get_ips=False)
  File "/var/lib/juju/agents/unit-mysql-k8s-2/charm/lib/charms/mysql/v0/mysql.py", line 1469, in get_cluster_endpoints
    raise MySQLGetClusterEndpointsError("Failed to get endpoints from cluster status")
charms.mysql.v0.mysql.MySQLGetClusterEndpointsError: Failed to get endpoints from cluster status
unit-mysql-k8s-0: 01:43:15 ERROR unit.mysql-k8s/0.juju-log Failed to get cluster status for test_cluster
unit-mysql-k8s-0: 01:43:15 ERROR unit.mysql-k8s/0.juju-log Failed to get cluster endpoints
Traceback (most recent call last):
  File "/var/lib/juju/agents/unit-mysql-k8s-0/charm/src/mysql_k8s_helpers.py", line 836, in update_endpoints
    rw_endpoints, ro_endpoints, offline = self.get_cluster_endpoints(get_ips=False)
  File "/var/lib/juju/agents/unit-mysql-k8s-0/charm/lib/charms/mysql/v0/mysql.py", line 1469, in get_cluster_endpoints
    raise MySQLGetClusterEndpointsError("Failed to get endpoints from cluster status")
charms.mysql.v0.mysql.MySQLGetClusterEndpointsError: Failed to get endpoints from cluster status

[32mINFO    [0m pytest_operator.plugin:plugin.py:862 Forgetting main...