[32mINFO    [0m pytest_operator.plugin:plugin.py:790 Model status:

Model    Controller          Cloud/Region        Version  SLA          Timestamp
testing  concierge-microk8s  microk8s/localhost  3.6.8    unsupported  01:46:04Z

App      Version                  Status       Scale  Charm             Channel      Rev  Address         Exposed  Message
app0     0.0.2                    active           1  mysql-test-app    latest/edge   73  10.152.183.198  no       Last written value=139
app1     0.0.2                    active           1  mysql-test-app    latest/edge   73  10.152.183.234  no       Last written value=353
app2     0.0.2                    active           1  mysql-test-app    latest/edge   73  10.152.183.200  no       Last written value=239
app3     0.0.2                    active           1  mysql-test-app    latest/edge   73  10.152.183.51   no       Last written value=210
app4     0.0.2                    active           1  mysql-test-app    latest/edge   73  10.152.183.46   no       Last written value=209
app5     0.0.2                    active           1  mysql-test-app    latest/edge   73  10.152.183.60   no       
app6     0.0.2                    active           1  mysql-test-app    latest/edge   73  10.152.183.175  no       Last written value=94
mysql    8.0.42-0ubuntu0.22.04.2  active           1  mysql-k8s                        0  10.152.183.218  no       
router0  8.0.42-0ubuntu0.22.04.2  active           1  mysql-router-k8s  8.0/edge     769  10.152.183.28   no       
router1  8.0.42-0ubuntu0.22.04.2  maintenance      1  mysql-router-k8s  8.0/edge     769  10.152.183.226  no       Waiting for K8s service connectivity
router2  8.0.42-0ubuntu0.22.04.2  active           1  mysql-router-k8s  8.0/edge     769  10.152.183.163  no       
router3  8.0.42-0ubuntu0.22.04.2  maintenance      1  mysql-router-k8s  8.0/edge     769  10.152.183.76   no       Waiting for K8s service connectivity
router4  8.0.42-0ubuntu0.22.04.2  active           1  mysql-router-k8s  8.0/edge     769  10.152.183.85   no       
router5  8.0.42-0ubuntu0.22.04.2  maintenance      1  mysql-router-k8s  8.0/edge     769  10.152.183.229  no       Waiting for K8s service connectivity
router6  8.0.42-0ubuntu0.22.04.2  maintenance      1  mysql-router-k8s  8.0/edge     769  10.152.183.204  no       Waiting for K8s service connectivity

Unit        Workload  Agent  Address     Ports  Message
app0/0*     active    idle   10.1.98.10         Last written value=139
app1/0*     active    idle   10.1.98.11         Last written value=353
app2/0*     active    idle   10.1.98.13         Last written value=239
app3/0*     active    idle   10.1.98.15         Last written value=210
app4/0*     active    idle   10.1.98.17         Last written value=209
app5/0*     active    idle   10.1.98.19         
app6/0*     active    idle   10.1.98.20         Last written value=94
mysql/0*    active    idle   10.1.98.9          Primary
router0/0*  active    idle   10.1.98.12         
router1/0*  active    idle   10.1.98.14         
router2/0*  active    idle   10.1.98.16         
router3/0*  active    idle   10.1.98.18         
router4/0*  active    idle   10.1.98.21         
router5/0*  active    idle   10.1.98.22         
router6/0*  active    idle   10.1.98.23         

[32mINFO    [0m pytest_operator.plugin:plugin.py:796 Juju error logs:

unit-router2-2: 01:37:06 ERROR unit.router2/2.juju-log backend-database:35: Failed to run MySQL Shell script:
import json
import mysqlsh
import traceback

try:
    # Disable wizards in this script, since it will be invoked without --no-wizard
    shell.options.set('useWizards', False)
    import json

    cluster_set = dba.get_cluster_set()
    routers = cluster_set.list_routers()
    # mysqlsh objects are weirdâ€”they quack (i.e. duck typing) like standard Python objects (e.g. list,
    # dict), but do not serialize to JSON correctly.
    # Cast to str & load from JSON str before serializing
    routers = json.loads(str(routers))
    with open("/tmp/mysqlsh_output.json", "w") as file:
        json.dump(routers, file)
except mysqlsh.DBError as exception:
    error = {
        "message": str(exception),
        "code": exception.code,
        "traceback_message": "".join(traceback.format_exception(exception)),
    }
else:
    error = None
with open("/tmp/mysqlsh_error.json", "w") as file:
    json.dump(error, file)

MySQL client error 1040
MySQL Shell traceback:
Traceback (most recent call last):
  File "<string>", line 10, in <module>
mysqlsh.DBError: MySQL Error (1040): Dba.get_cluster_set: Too many connections

Traceback (most recent call last):
  File "/var/lib/juju/agents/unit-router2-2/charm/src/mysql_shell/__init__.py", line 99, in _run_code
    raise ShellDBError(**exception)
mysql_shell.ShellDBError: MySQL Error (1040): Dba.get_cluster_set: Too many connections
unit-router2-2: 01:37:06 ERROR unit.router2/2.juju-log backend-database:35: Uncaught exception while in charm code:
Traceback (most recent call last):
  File "/var/lib/juju/agents/unit-router2-2/charm/src/charm.py", line 454, in <module>
    ops.main.main(KubernetesRouterCharm)
  File "/var/lib/juju/agents/unit-router2-2/charm/venv/lib/python3.10/site-packages/ops/main.py", line 436, in main
    _emit_charm_event(charm, dispatcher.event_name)
  File "/var/lib/juju/agents/unit-router2-2/charm/venv/lib/python3.10/site-packages/ops/main.py", line 144, in _emit_charm_event
    event_to_emit.emit(*args, **kwargs)
  File "/var/lib/juju/agents/unit-router2-2/charm/venv/lib/python3.10/site-packages/ops/framework.py", line 351, in emit
    framework._emit(event)
  File "/var/lib/juju/agents/unit-router2-2/charm/venv/lib/python3.10/site-packages/ops/framework.py", line 853, in _emit
    self._reemit(event_path)
  File "/var/lib/juju/agents/unit-router2-2/charm/venv/lib/python3.10/site-packages/ops/framework.py", line 942, in _reemit
    custom_handler(event)
  File "/var/lib/juju/agents/unit-router2-2/charm/lib/charms/data_platform_libs/v0/data_interfaces.py", line 3141, in _on_relation_changed_event
    getattr(self.on, "database_created").emit(
  File "/var/lib/juju/agents/unit-router2-2/charm/venv/lib/python3.10/site-packages/ops/framework.py", line 351, in emit
    framework._emit(event)
  File "/var/lib/juju/agents/unit-router2-2/charm/venv/lib/python3.10/site-packages/ops/framework.py", line 853, in _emit
    self._reemit(event_path)
  File "/var/lib/juju/agents/unit-router2-2/charm/venv/lib/python3.10/site-packages/ops/framework.py", line 942, in _reemit
    custom_handler(event)
  File "/var/lib/juju/agents/unit-router2-2/charm/lib/charms/tempo_coordinator_k8s/v0/charm_tracing.py", line 735, in wrapped_function
    return callable(*args, **kwargs)  # type: ignore
  File "/var/lib/juju/agents/unit-router2-2/charm/src/abstract_charm.py", line 375, in reconcile
    self.set_status(event=event)
  File "/var/lib/juju/agents/unit-router2-2/charm/lib/charms/tempo_coordinator_k8s/v0/charm_tracing.py", line 735, in wrapped_function
    return callable(*args, **kwargs)  # type: ignore
  File "/var/lib/juju/agents/unit-router2-2/charm/src/abstract_charm.py", line 232, in set_status
    self.unit.status = self._determine_unit_status(event=event)
  File "/var/lib/juju/agents/unit-router2-2/charm/lib/charms/tempo_coordinator_k8s/v0/charm_tracing.py", line 735, in wrapped_function
    return callable(*args, **kwargs)  # type: ignore
  File "/var/lib/juju/agents/unit-router2-2/charm/src/abstract_charm.py", line 217, in _determine_unit_status
    workload_status = self.get_workload(event=event).status
  File "/var/lib/juju/agents/unit-router2-2/charm/src/workload.py", line 423, in status
    if not self.shell.is_router_in_cluster_set(self._router_id):
  File "/var/lib/juju/agents/unit-router2-2/charm/src/mysql_shell/__init__.py", line 214, in is_router_in_cluster_set
    self._run_code(
  File "/var/lib/juju/agents/unit-router2-2/charm/src/mysql_shell/__init__.py", line 99, in _run_code
    raise ShellDBError(**exception)
mysql_shell.ShellDBError: MySQL Error (1040): Dba.get_cluster_set: Too many connections
unit-router2-2: 01:37:07 ERROR juju.worker.uniter.operation hook "backend-database-relation-changed" (via hook dispatching script: dispatch) failed: exit status 1
unit-mysql-2: 01:38:07 ERROR unit.mysql/2.juju-log Failed to execute MySQL cli command
Traceback (most recent call last):
  File "/var/lib/juju/agents/unit-mysql-2/charm/src/mysql_k8s_helpers.py", line 773, in _run_mysqlcli_script
    stdout, _ = process.wait_output()
  File "/var/lib/juju/agents/unit-mysql-2/charm/venv/lib/python3.10/site-packages/ops/pebble.py", line 1771, in wait_output
    raise ExecError[AnyStr](self._command, exit_code, out_value, err_value)
ops.pebble.ExecError: non-zero exit code 1 executing ['/usr/bin/mysql', '-u', 'root', '-p', '-N', '--socket=/var/run/mysqld/mysqld.sock', '-e', "CREATE USER 'serverconfig'@'%' IDENTIFIED BY '*****';GRANT ALL ON *.* TO 'serverconfig'@'%' WITH GRANT OPTION;CREATE USER 'monitoring'@'%' IDENTIFIED BY '*****' WITH MAX_USER_CONNECTIONS 3;GRANT SYSTEM_USER, SELECT, PROCESS, SUPER, REPLICATION CLIENT, RELOAD ON *.* TO 'monitoring'@'%';CREATE USER 'backups'@'%' IDENTIFIED BY '*****';GRANT CONNECTION_ADMIN, BACKUP_ADMIN, PROCESS, RELOAD, LOCK TABLES, REPLICATION CLIENT ON *.* TO 'backups'@'%';GRANT SELECT ON performance_schema.log_status TO 'backups'@'%';GRANT SELECT ON performance_schema.keyring_component_status TO 'backups'@'%';GRANT SELECT ON performance_schema.replication_group_members TO 'backups'@'%';UPDATE mysql.user SET authentication_string=null WHERE User='root' and Host='localhost';ALTER USER 'root'@'localhost' IDENTIFIED BY '*****';REVOKE SYSTEM_USER, SYSTEM_VARIABLES_ADMIN, SUPER, REPLICATION_SLAVE_ADMIN, GROUP_REPLICATION_ADMIN, BINLOG_ADMIN, SET_USER_ID, ENCRYPTION_KEY_ADMIN, VERSION_TOKEN_ADMIN, CONNECTION_ADMIN ON *.* FROM 'root'@'localhost';FLUSH PRIVILEGES"], stdout='', stderr="Enter password: ERROR 2002 (HY000): Can't connect to local MySQL server through socket '/var/run/mysqld/mysqld.sock' (2)\n"
unit-mysql-2: 01:38:07 ERROR unit.mysql/2.juju-log Failed to configure users for: mysql-2.mysql-endpoints.testing.svc.cluster.local.
unit-mysql-2: 01:38:08 ERROR unit.mysql/2.juju-log Uncaught exception while in charm code:
Traceback (most recent call last):
  File "/var/lib/juju/agents/unit-mysql-2/charm/src/mysql_k8s_helpers.py", line 773, in _run_mysqlcli_script
    stdout, _ = process.wait_output()
  File "/var/lib/juju/agents/unit-mysql-2/charm/venv/lib/python3.10/site-packages/ops/pebble.py", line 1771, in wait_output
    raise ExecError[AnyStr](self._command, exit_code, out_value, err_value)
ops.pebble.ExecError: non-zero exit code 1 executing ['/usr/bin/mysql', '-u', 'root', '-p', '-N', '--socket=/var/run/mysqld/mysqld.sock', '-e', "CREATE USER 'serverconfig'@'%' IDENTIFIED BY '*****';GRANT ALL ON *.* TO 'serverconfig'@'%' WITH GRANT OPTION;CREATE USER 'monitoring'@'%' IDENTIFIED BY '*****' WITH MAX_USER_CONNECTIONS 3;GRANT SYSTEM_USER, SELECT, PROCESS, SUPER, REPLICATION CLIENT, RELOAD ON *.* TO 'monitoring'@'%';CREATE USER 'backups'@'%' IDENTIFIED BY '*****';GRANT CONNECTION_ADMIN, BACKUP_ADMIN, PROCESS, RELOAD, LOCK TABLES, REPLICATION CLIENT ON *.* TO 'backups'@'%';GRANT SELECT ON performance_schema.log_status TO 'backups'@'%';GRANT SELECT ON performance_schema.keyring_component_status TO 'backups'@'%';GRANT SELECT ON performance_schema.replication_group_members TO 'backups'@'%';UPDATE mysql.user SET authentication_string=null WHERE User='root' and Host='localhost';ALTER USER 'root'@'localhost' IDENTIFIED BY '*****';REVOKE SYSTEM_USER, SYSTEM_VARIABLES_ADMIN, SUPER, REPLICATION_SLAVE_ADMIN, GROUP_REPLICATION_ADMIN, BINLOG_ADMIN, SET_USER_ID, ENCRYPTION_KEY_ADMIN, VERSION_TOKEN_ADMIN, CONNECTION_ADMIN ON *.* FROM 'root'@'localhost';FLUSH PRIVILEGES"], stdout='', stderr="Enter password: ERROR 2002 (HY000): Can't connect to local MySQL server through socket '/var/run/mysqld/mysqld.sock' (2)\n"

During handling of the above exception, another exception occurred:

Traceback (most recent call last):
  File "/var/lib/juju/agents/unit-mysql-2/charm/lib/charms/mysql/v0/mysql.py", line 1137, in configure_mysql_users
    self._run_mysqlcli_script(
  File "/var/lib/juju/agents/unit-mysql-2/charm/lib/charms/tempo_coordinator_k8s/v0/charm_tracing.py", line 1065, in wrapped_function
    return callable(*args, **kwargs)  # type: ignore
  File "/var/lib/juju/agents/unit-mysql-2/charm/src/mysql_k8s_helpers.py", line 781, in _run_mysqlcli_script
    raise MySQLClientError
charms.mysql.v0.mysql.MySQLClientError

During handling of the above exception, another exception occurred:

Traceback (most recent call last):
  File "/var/lib/juju/agents/unit-mysql-2/charm/src/charm.py", line 1102, in <module>
    main(MySQLOperatorCharm)
  File "/var/lib/juju/agents/unit-mysql-2/charm/venv/lib/python3.10/site-packages/ops/main.py", line 551, in main
    manager.run()
  File "/var/lib/juju/agents/unit-mysql-2/charm/venv/lib/python3.10/site-packages/ops/main.py", line 530, in run
    self._emit()
  File "/var/lib/juju/agents/unit-mysql-2/charm/venv/lib/python3.10/site-packages/ops/main.py", line 519, in _emit
    _emit_charm_event(self.charm, self.dispatcher.event_name)
  File "/var/lib/juju/agents/unit-mysql-2/charm/venv/lib/python3.10/site-packages/ops/main.py", line 147, in _emit_charm_event
    event_to_emit.emit(*args, **kwargs)
  File "/var/lib/juju/agents/unit-mysql-2/charm/venv/lib/python3.10/site-packages/ops/framework.py", line 348, in emit
    framework._emit(event)
  File "/var/lib/juju/agents/unit-mysql-2/charm/venv/lib/python3.10/site-packages/ops/framework.py", line 860, in _emit
    self._reemit(event_path)
  File "/var/lib/juju/agents/unit-mysql-2/charm/venv/lib/python3.10/site-packages/ops/framework.py", line 950, in _reemit
    custom_handler(event)
  File "/var/lib/juju/agents/unit-mysql-2/charm/lib/charms/tempo_coordinator_k8s/v0/charm_tracing.py", line 1065, in wrapped_function
    return callable(*args, **kwargs)  # type: ignore
  File "/var/lib/juju/agents/unit-mysql-2/charm/src/charm.py", line 829, in _on_mysql_pebble_ready
    self._configure_instance(container)
  File "/var/lib/juju/agents/unit-mysql-2/charm/lib/charms/tempo_coordinator_k8s/v0/charm_tracing.py", line 1065, in wrapped_function
    return callable(*args, **kwargs)  # type: ignore
  File "/var/lib/juju/agents/unit-mysql-2/charm/src/charm.py", line 728, in _configure_instance
    self._mysql.configure_mysql_users()
  File "/var/lib/juju/agents/unit-mysql-2/charm/lib/charms/tempo_coordinator_k8s/v0/charm_tracing.py", line 1065, in wrapped_function
    return callable(*args, **kwargs)  # type: ignore
  File "/var/lib/juju/agents/unit-mysql-2/charm/lib/charms/mysql/v0/mysql.py", line 1143, in configure_mysql_users
    raise MySQLConfigureMySQLUsersError
charms.mysql.v0.mysql.MySQLConfigureMySQLUsersError
unit-mysql-2: 01:38:11 ERROR juju.worker.uniter.operation hook "mysql-pebble-ready" (via hook dispatching script: dispatch) failed: exit status 1
unit-mysql-2: 01:38:11 ERROR juju.worker.uniter pebble poll failed for container "mysql": failed to send pebble-ready event: hook failed
unit-mysql-2: 01:38:38 ERROR unit.mysql/2.juju-log Failed to initialise MySQL data directory
Traceback (most recent call last):
  File "/var/lib/juju/agents/unit-mysql-2/charm/src/mysql_k8s_helpers.py", line 228, in initialise_mysqld
    process.wait()
  File "/var/lib/juju/agents/unit-mysql-2/charm/venv/lib/python3.10/site-packages/ops/pebble.py", line 1697, in wait
    raise ExecError(self._command, exit_code, None, None)
ops.pebble.ExecError: non-zero exit code 1 executing ['/usr/sbin/mysqld', '--initialize', '-u', 'mysql']
unit-mysql-1: 01:45:44 ERROR juju.worker.dependency "log-sender" manifold worker returned unexpected error: sending log message: websocket: close 1005 (no status): websocket: close sent
unit-app1-0: 01:45:56 ERROR juju.worker.dependency "log-sender" manifold worker returned unexpected error: sending log message: websocket: close 1005 (no status): websocket: close sent

[32mINFO    [0m pytest_operator.plugin:plugin.py:862 Forgetting main...