[32mINFO    [0m integration.test_charm:test_charm.py:341 Checking that max_connections is set to 100 on mysql-k8s/0
[32mINFO    [0m integration.test_charm:test_charm.py:341 Checking that innodb_buffer_pool_size is set to 20971520 on mysql-k8s/0
[32mINFO    [0m integration.test_charm:test_charm.py:341 Checking that innodb_buffer_pool_chunk_size is set to 1048576 on mysql-k8s/0
[32mINFO    [0m integration.test_charm:test_charm.py:341 Checking that group_replication_message_cache_size is set to 134217728 on mysql-k8s/0
[32mINFO    [0m integration.test_charm:test_charm.py:341 Checking that max_connections is set to 100 on mysql-k8s/1
[32mINFO    [0m integration.test_charm:test_charm.py:341 Checking that innodb_buffer_pool_size is set to 20971520 on mysql-k8s/1
[32mINFO    [0m integration.test_charm:test_charm.py:341 Checking that innodb_buffer_pool_chunk_size is set to 1048576 on mysql-k8s/1
[32mINFO    [0m integration.test_charm:test_charm.py:341 Checking that group_replication_message_cache_size is set to 134217728 on mysql-k8s/1
[32mINFO    [0m integration.test_charm:test_charm.py:341 Checking that max_connections is set to 100 on mysql-k8s/2
[32mINFO    [0m integration.test_charm:test_charm.py:341 Checking that innodb_buffer_pool_size is set to 20971520 on mysql-k8s/2
[32mINFO    [0m integration.test_charm:test_charm.py:341 Checking that innodb_buffer_pool_chunk_size is set to 1048576 on mysql-k8s/2
[32mINFO    [0m integration.test_charm:test_charm.py:341 Checking that group_replication_message_cache_size is set to 134217728 on mysql-k8s/2
[32mINFO    [0m pytest_operator.plugin:plugin.py:790 Model status:

Model    Controller          Cloud/Region        Version  SLA          Timestamp
testing  concierge-microk8s  microk8s/localhost  3.6.8    unsupported  02:03:03Z

App        Version  Status  Scale  Charm      Channel  Rev  Address         Exposed  Message
mysql-k8s           active      3  mysql-k8s             0  10.152.183.116  no       

Unit          Workload  Agent  Address     Ports  Message
mysql-k8s/0   active    idle   10.1.98.20         
mysql-k8s/1*  active    idle   10.1.98.22         Primary
mysql-k8s/2   active    idle   10.1.98.21         

[32mINFO    [0m pytest_operator.plugin:plugin.py:796 Juju error logs:

unit-mysql-k8s-0: 01:56:00 ERROR unit.mysql-k8s/0.juju-log Uncaught exception while in charm code:
Traceback (most recent call last):
  File "/var/lib/juju/agents/unit-mysql-k8s-0/charm/src/charm.py", line 1102, in <module>
    main(MySQLOperatorCharm)
  File "/var/lib/juju/agents/unit-mysql-k8s-0/charm/venv/lib/python3.10/site-packages/ops/main.py", line 551, in main
    manager.run()
  File "/var/lib/juju/agents/unit-mysql-k8s-0/charm/venv/lib/python3.10/site-packages/ops/main.py", line 530, in run
    self._emit()
  File "/var/lib/juju/agents/unit-mysql-k8s-0/charm/venv/lib/python3.10/site-packages/ops/main.py", line 519, in _emit
    _emit_charm_event(self.charm, self.dispatcher.event_name)
  File "/var/lib/juju/agents/unit-mysql-k8s-0/charm/venv/lib/python3.10/site-packages/ops/main.py", line 147, in _emit_charm_event
    event_to_emit.emit(*args, **kwargs)
  File "/var/lib/juju/agents/unit-mysql-k8s-0/charm/venv/lib/python3.10/site-packages/ops/framework.py", line 348, in emit
    framework._emit(event)
  File "/var/lib/juju/agents/unit-mysql-k8s-0/charm/venv/lib/python3.10/site-packages/ops/framework.py", line 860, in _emit
    self._reemit(event_path)
  File "/var/lib/juju/agents/unit-mysql-k8s-0/charm/venv/lib/python3.10/site-packages/ops/framework.py", line 950, in _reemit
    custom_handler(event)
  File "/var/lib/juju/agents/unit-mysql-k8s-0/charm/lib/charms/tempo_coordinator_k8s/v0/charm_tracing.py", line 1065, in wrapped_function
    return callable(*args, **kwargs)  # type: ignore
  File "/var/lib/juju/agents/unit-mysql-k8s-0/charm/src/relations/mysql_provider.py", line 255, in _on_update_status
    self.charm._mysql.update_endpoints(DB_RELATION_NAME)
  File "/var/lib/juju/agents/unit-mysql-k8s-0/charm/lib/charms/tempo_coordinator_k8s/v0/charm_tracing.py", line 1065, in wrapped_function
    return callable(*args, **kwargs)  # type: ignore
  File "/var/lib/juju/agents/unit-mysql-k8s-0/charm/src/mysql_k8s_helpers.py", line 906, in update_endpoints
    rw_endpoints, ro_endpoints, offline = self.charm.get_cluster_endpoints(relation_name)
  File "/var/lib/juju/agents/unit-mysql-k8s-0/charm/lib/charms/tempo_coordinator_k8s/v0/charm_tracing.py", line 1065, in wrapped_function
    return callable(*args, **kwargs)  # type: ignore
  File "/var/lib/juju/agents/unit-mysql-k8s-0/charm/lib/charms/mysql/v0/mysql.py", line 803, in get_cluster_endpoints
    address = f"{self.get_unit_address(unit_labels[k], relation_name)}:3306"
KeyError: 'mysql-k8s-1'
unit-mysql-k8s-0: 01:56:01 ERROR juju.worker.uniter.operation hook "update-status" (via hook dispatching script: dispatch) failed: exit status 1
unit-mysql-k8s-2: 01:59:05 ERROR unit.mysql-k8s/2.juju-log Failed to execute mysql-shell command
Traceback (most recent call last):
  File "/var/lib/juju/agents/unit-mysql-k8s-2/charm/src/mysql_k8s_helpers.py", line 724, in _run_mysqlsh_script
    stdout, _ = process.wait_output()
  File "/var/lib/juju/agents/unit-mysql-k8s-2/charm/venv/lib/python3.10/site-packages/ops/pebble.py", line 1771, in wait_output
    raise ExecError[AnyStr](self._command, exit_code, out_value, err_value)
ops.pebble.ExecError: non-zero exit code 1 executing ['timeout', '30', '/usr/bin/mysqlsh', '--passwords-from-stdin', '--uri=serverconfig@mysql-k8s-2.mysql-k8s-endpoints.testing.svc.cluster.local.:33062', '--python', '--verbose=0', '-c', "shell.options.set('useWizards', False)\nprint('###')\ncluster = dba.get_cluster('test_cluster')\nprint(cluster.status({'extended': False}))"], stdout="\x1b[1mPlease provide the password for 'serverconfig@mysql-k8s-2.mysql-k8s-endpoints.testing.svc.cluster.local.:33062': \x1b[0m###\n", stderr='Cannot set LC_ALL to locale en_US.UTF-8: No such file or directory\n\x1b[33mWARNING: \x1b[0mError connecting to Cluster: MYSQLSH 51104: Metadata for instance a9ff3a6d-6ce7-11f0-aaa0-2e1ec746a609 not found\nTraceback (most recent call last):\n  File "<string>", line 3, in <module>\nmysqlsh.Error: Shell Error (51104): Dba.get_cluster: Metadata for instance a9ff3a6d-6ce7-11f0-aaa0-2e1ec746a609 not found\n'
unit-mysql-k8s-2: 01:59:05 ERROR unit.mysql-k8s/2.juju-log Failed to get cluster status for test_cluster
unit-mysql-k8s-1: 01:59:05 ERROR unit.mysql-k8s/1.juju-log Failed to execute mysql-shell command
Traceback (most recent call last):
  File "/var/lib/juju/agents/unit-mysql-k8s-1/charm/src/mysql_k8s_helpers.py", line 724, in _run_mysqlsh_script
    stdout, _ = process.wait_output()
  File "/var/lib/juju/agents/unit-mysql-k8s-1/charm/venv/lib/python3.10/site-packages/ops/pebble.py", line 1771, in wait_output
    raise ExecError[AnyStr](self._command, exit_code, out_value, err_value)
ops.pebble.ExecError: non-zero exit code 1 executing ['timeout', '30', '/usr/bin/mysqlsh', '--passwords-from-stdin', '--uri=serverconfig@mysql-k8s-1.mysql-k8s-endpoints.testing.svc.cluster.local.:33062', '--python', '--verbose=0', '-c', "shell.options.set('useWizards', False)\nprint('###')\ncluster = dba.get_cluster('test_cluster')\nprint(cluster.status({'extended': False}))"], stdout="\x1b[1mPlease provide the password for 'serverconfig@mysql-k8s-1.mysql-k8s-endpoints.testing.svc.cluster.local.:33062': \x1b[0m###\n", stderr='Cannot set LC_ALL to locale en_US.UTF-8: No such file or directory\n\x1b[33mWARNING: \x1b[0mError connecting to Cluster: MYSQLSH 51104: Metadata for instance a9ff3a6d-6ce7-11f0-aaa0-2e1ec746a609 not found\nTraceback (most recent call last):\n  File "<string>", line 3, in <module>\nmysqlsh.Error: Shell Error (51104): Dba.get_cluster: Metadata for instance a9ff3a6d-6ce7-11f0-aaa0-2e1ec746a609 not found\n'
unit-mysql-k8s-1: 01:59:05 ERROR unit.mysql-k8s/1.juju-log Failed to get cluster status for test_cluster

[32mINFO    [0m pytest_operator.plugin:plugin.py:862 Forgetting main...