[32mINFO    [0m integration.test_charm:test_charm.py:341 Checking that max_connections is set to 100 on mysql-k8s/0
[32mINFO    [0m integration.test_charm:test_charm.py:341 Checking that innodb_buffer_pool_size is set to 20971520 on mysql-k8s/0
[32mINFO    [0m integration.test_charm:test_charm.py:341 Checking that innodb_buffer_pool_chunk_size is set to 1048576 on mysql-k8s/0
[32mINFO    [0m integration.test_charm:test_charm.py:341 Checking that group_replication_message_cache_size is set to 134217728 on mysql-k8s/0
[32mINFO    [0m integration.test_charm:test_charm.py:341 Checking that max_connections is set to 100 on mysql-k8s/1
[32mINFO    [0m integration.test_charm:test_charm.py:341 Checking that innodb_buffer_pool_size is set to 20971520 on mysql-k8s/1
[32mINFO    [0m integration.test_charm:test_charm.py:341 Checking that innodb_buffer_pool_chunk_size is set to 1048576 on mysql-k8s/1
[32mINFO    [0m integration.test_charm:test_charm.py:341 Checking that group_replication_message_cache_size is set to 134217728 on mysql-k8s/1
[32mINFO    [0m integration.test_charm:test_charm.py:341 Checking that max_connections is set to 100 on mysql-k8s/2
[32mINFO    [0m integration.test_charm:test_charm.py:341 Checking that innodb_buffer_pool_size is set to 20971520 on mysql-k8s/2
[32mINFO    [0m integration.test_charm:test_charm.py:341 Checking that innodb_buffer_pool_chunk_size is set to 1048576 on mysql-k8s/2
[32mINFO    [0m integration.test_charm:test_charm.py:341 Checking that group_replication_message_cache_size is set to 134217728 on mysql-k8s/2
[32mINFO    [0m pytest_operator.plugin:plugin.py:790 Model status:

Model    Controller          Cloud/Region        Version  SLA          Timestamp
testing  concierge-microk8s  microk8s/localhost  3.6.8    unsupported  01:42:01Z

App        Version  Status  Scale  Charm      Channel  Rev  Address         Exposed  Message
mysql-k8s           active      3  mysql-k8s             0  10.152.183.195  no       

Unit          Workload  Agent      Address      Ports  Message
mysql-k8s/0   active    executing  10.1.63.212         
mysql-k8s/1   active    idle       10.1.63.214         
mysql-k8s/2*  active    executing  10.1.63.213         Primary

[32mINFO    [0m pytest_operator.plugin:plugin.py:796 Juju error logs:

unit-mysql-k8s-3: 01:32:29 ERROR unit.mysql-k8s/3.juju-log Failed to execute mysql-shell command
Traceback (most recent call last):
  File "/var/lib/juju/agents/unit-mysql-k8s-3/charm/venv/lib/python3.10/site-packages/websocket/_socket.py", line 118, in recv
    bytes_ = _recv()
  File "/var/lib/juju/agents/unit-mysql-k8s-3/charm/venv/lib/python3.10/site-packages/websocket/_socket.py", line 97, in _recv
    return sock.recv(bufsize)
TimeoutError: timed out

During handling of the above exception, another exception occurred:

Traceback (most recent call last):
  File "/var/lib/juju/agents/unit-mysql-k8s-3/charm/venv/lib/python3.10/site-packages/ops/pebble.py", line 2890, in exec
    control_ws = self._connect_websocket(task_id, 'control')
  File "/var/lib/juju/agents/unit-mysql-k8s-3/charm/venv/lib/python3.10/site-packages/ops/pebble.py", line 2978, in _connect_websocket
    ws.connect(url, socket=sock)
  File "/var/lib/juju/agents/unit-mysql-k8s-3/charm/venv/lib/python3.10/site-packages/websocket/_core.py", line 261, in connect
    self.handshake_response = handshake(self.sock, url, *addrs, **options)
  File "/var/lib/juju/agents/unit-mysql-k8s-3/charm/venv/lib/python3.10/site-packages/websocket/_handshake.py", line 65, in handshake
    status, resp = _get_resp_headers(sock)
  File "/var/lib/juju/agents/unit-mysql-k8s-3/charm/venv/lib/python3.10/site-packages/websocket/_handshake.py", line 141, in _get_resp_headers
    status, resp_headers, status_message = read_headers(sock)
  File "/var/lib/juju/agents/unit-mysql-k8s-3/charm/venv/lib/python3.10/site-packages/websocket/_http.py", line 351, in read_headers
    line = recv_line(sock)
  File "/var/lib/juju/agents/unit-mysql-k8s-3/charm/venv/lib/python3.10/site-packages/websocket/_socket.py", line 140, in recv_line
    c = recv(sock, 1)
  File "/var/lib/juju/agents/unit-mysql-k8s-3/charm/venv/lib/python3.10/site-packages/websocket/_socket.py", line 120, in recv
    raise WebSocketTimeoutException("Connection timed out")
websocket._exceptions.WebSocketTimeoutException: Connection timed out

The above exception was the direct cause of the following exception:

Traceback (most recent call last):
  File "/var/lib/juju/agents/unit-mysql-k8s-3/charm/src/mysql_k8s_helpers.py", line 723, in _run_mysqlsh_script
    process = self.container.exec(cmd, stdin=password)
  File "/var/lib/juju/agents/unit-mysql-k8s-3/charm/venv/lib/python3.10/site-packages/ops/model.py", line 2872, in exec
    return self._pebble.exec(
  File "/var/lib/juju/agents/unit-mysql-k8s-3/charm/venv/lib/python3.10/site-packages/ops/pebble.py", line 2899, in exec
    raise ChangeError(change.err, change) from e
ops.pebble.ChangeError: cannot perform the following tasks:
- Execute command "/usr/bin/mysqlsh" (exec 18: timeout waiting for websocket connections: context deadline exceeded)
----- Logs from task 0 -----
2025-07-21T01:32:29Z ERROR exec 18: timeout waiting for websocket connections: context deadline exceeded
-----
unit-mysql-k8s-2: 01:34:44 ERROR unit.mysql-k8s/2.juju-log Uncaught exception while in charm code:
Traceback (most recent call last):
  File "/var/lib/juju/agents/unit-mysql-k8s-2/charm/src/charm.py", line 1102, in <module>
    main(MySQLOperatorCharm)
  File "/var/lib/juju/agents/unit-mysql-k8s-2/charm/venv/lib/python3.10/site-packages/ops/main.py", line 551, in main
    manager.run()
  File "/var/lib/juju/agents/unit-mysql-k8s-2/charm/venv/lib/python3.10/site-packages/ops/main.py", line 530, in run
    self._emit()
  File "/var/lib/juju/agents/unit-mysql-k8s-2/charm/venv/lib/python3.10/site-packages/ops/main.py", line 519, in _emit
    _emit_charm_event(self.charm, self.dispatcher.event_name)
  File "/var/lib/juju/agents/unit-mysql-k8s-2/charm/venv/lib/python3.10/site-packages/ops/main.py", line 147, in _emit_charm_event
    event_to_emit.emit(*args, **kwargs)
  File "/var/lib/juju/agents/unit-mysql-k8s-2/charm/venv/lib/python3.10/site-packages/ops/framework.py", line 348, in emit
    framework._emit(event)
  File "/var/lib/juju/agents/unit-mysql-k8s-2/charm/venv/lib/python3.10/site-packages/ops/framework.py", line 860, in _emit
    self._reemit(event_path)
  File "/var/lib/juju/agents/unit-mysql-k8s-2/charm/venv/lib/python3.10/site-packages/ops/framework.py", line 950, in _reemit
    custom_handler(event)
  File "/var/lib/juju/agents/unit-mysql-k8s-2/charm/lib/charms/tempo_coordinator_k8s/v0/charm_tracing.py", line 1065, in wrapped_function
    return callable(*args, **kwargs)  # type: ignore
  File "/var/lib/juju/agents/unit-mysql-k8s-2/charm/src/charm.py", line 1076, in _on_database_storage_detaching
    self._mysql.set_cluster_primary(
  File "/var/lib/juju/agents/unit-mysql-k8s-2/charm/lib/charms/tempo_coordinator_k8s/v0/charm_tracing.py", line 1065, in wrapped_function
    return callable(*args, **kwargs)  # type: ignore
  File "/var/lib/juju/agents/unit-mysql-k8s-2/charm/src/mysql_k8s_helpers.py", line 924, in set_cluster_primary
    self.update_endpoints(PEER)
  File "/var/lib/juju/agents/unit-mysql-k8s-2/charm/lib/charms/tempo_coordinator_k8s/v0/charm_tracing.py", line 1065, in wrapped_function
    return callable(*args, **kwargs)  # type: ignore
  File "/var/lib/juju/agents/unit-mysql-k8s-2/charm/src/mysql_k8s_helpers.py", line 906, in update_endpoints
    rw_endpoints, ro_endpoints, offline = self.charm.get_cluster_endpoints(relation_name)
  File "/var/lib/juju/agents/unit-mysql-k8s-2/charm/lib/charms/tempo_coordinator_k8s/v0/charm_tracing.py", line 1065, in wrapped_function
    return callable(*args, **kwargs)  # type: ignore
  File "/var/lib/juju/agents/unit-mysql-k8s-2/charm/lib/charms/mysql/v0/mysql.py", line 803, in get_cluster_endpoints
    address = f"{self.get_unit_address(unit_labels[k], relation_name)}:3306"
KeyError: 'mysql-k8s-1'
unit-mysql-k8s-2: 01:34:45 ERROR juju.worker.uniter.operation hook "database-storage-detaching" (via hook dispatching script: dispatch) failed: exit status 1

[32mINFO    [0m pytest_operator.plugin:plugin.py:862 Forgetting main...