[32mINFO    [0m pytest_operator.plugin:plugin.py:790 Model status:

Model    Controller          Cloud/Region        Version  SLA          Timestamp
testing  concierge-microk8s  microk8s/localhost  3.6.8    unsupported  01:42:53Z

App      Version                  Status       Scale  Charm             Channel      Rev  Address         Exposed  Message
app0     0.0.2                    active           1  mysql-test-app    latest/edge   73  10.152.183.22   no       Last written value=244
app1     0.0.2                    active           1  mysql-test-app    latest/edge   73  10.152.183.108  no       Last written value=253
app2     0.0.2                    active           1  mysql-test-app    latest/edge   73  10.152.183.192  no       Last written value=182
app3     0.0.2                    active           1  mysql-test-app    latest/edge   73  10.152.183.117  no       Last written value=227
app4     0.0.2                    active           1  mysql-test-app    latest/edge   73  10.152.183.148  no       Last written value=245
app5     0.0.2                    active           1  mysql-test-app    latest/edge   73  10.152.183.33   no       Last written value=197
app6     0.0.2                    active           1  mysql-test-app    latest/edge   73  10.152.183.206  no       Last written value=204
mysql    8.0.41-0ubuntu0.22.04.1  active           1  mysql-k8s                        0  10.152.183.126  no       
router0  8.0.41-0ubuntu0.22.04.1  maintenance      1  mysql-router-k8s  8.0/edge     753  10.152.183.89   no       Waiting for K8s service connectivity
router1  8.0.41-0ubuntu0.22.04.1  active           1  mysql-router-k8s  8.0/edge     753  10.152.183.151  no       
router2  8.0.41-0ubuntu0.22.04.1  maintenance      1  mysql-router-k8s  8.0/edge     753  10.152.183.133  no       Waiting for K8s service connectivity
router3  8.0.41-0ubuntu0.22.04.1  maintenance      1  mysql-router-k8s  8.0/edge     753  10.152.183.84   no       Waiting for K8s service connectivity
router4  8.0.41-0ubuntu0.22.04.1  active           1  mysql-router-k8s  8.0/edge     753  10.152.183.139  no       
router5  8.0.41-0ubuntu0.22.04.1  maintenance      1  mysql-router-k8s  8.0/edge     753  10.152.183.140  no       Waiting for K8s service connectivity
router6  8.0.41-0ubuntu0.22.04.1  maintenance      1  mysql-router-k8s  8.0/edge     753  10.152.183.50   no       Waiting for K8s service connectivity

Unit        Workload  Agent  Address      Ports  Message
app0/0*     active    idle   10.1.63.202         Last written value=244
app1/0*     active    idle   10.1.63.203         Last written value=253
app2/0*     active    idle   10.1.63.205         Last written value=182
app3/0*     active    idle   10.1.63.207         Last written value=227
app4/0*     active    idle   10.1.63.208         Last written value=245
app5/0*     active    idle   10.1.63.210         Last written value=197
app6/0*     active    idle   10.1.63.212         Last written value=204
mysql/0*    active    idle   10.1.63.201         Primary
router0/0*  active    idle   10.1.63.204         
router1/0*  active    idle   10.1.63.206         
router2/0*  active    idle   10.1.63.209         
router3/0*  active    idle   10.1.63.211         
router4/0*  active    idle   10.1.63.213         
router5/0*  active    idle   10.1.63.214         
router6/0*  active    idle   10.1.63.215         

[32mINFO    [0m pytest_operator.plugin:plugin.py:796 Juju error logs:

unit-router6-2: 01:39:59 ERROR unit.router6/2.juju-log database:44: Failed to run MySQL Shell script:
import json
import mysqlsh
import traceback

try:
    # Disable wizards in this script, since it will be invoked without --no-wizard
    shell.options.set('useWizards', False)
    import json

    cluster_set = dba.get_cluster_set()
    routers = cluster_set.list_routers()
    # mysqlsh objects are weirdâ€”they quack (i.e. duck typing) like standard Python objects (e.g. list,
    # dict), but do not serialize to JSON correctly.
    # Cast to str & load from JSON str before serializing
    routers = json.loads(str(routers))
    with open("/tmp/mysqlsh_output.json", "w") as file:
        json.dump(routers, file)
except mysqlsh.DBError as exception:
    error = {
        "message": str(exception),
        "code": exception.code,
        "traceback_message": "".join(traceback.format_exception(exception)),
    }
else:
    error = None
with open("/tmp/mysqlsh_error.json", "w") as file:
    json.dump(error, file)

stderr:
Cannot set LC_ALL to locale en_US.UTF-8: No such file or directory
Traceback (most recent call last):
  File "<string>", line 11, in <module>
mysqlsh.Error: Shell Error (51603): ClusterSet.list_routers: Could not connect to PRIMARY of Primary Cluster 'cluster-6d308c0e988834f2cfb622ed306a10d5'

Traceback (most recent call last):
  File "/var/lib/juju/agents/unit-router6-2/charm/src/rock.py", line 250, in _run_command
    output, _ = process.wait_output()
  File "/var/lib/juju/agents/unit-router6-2/charm/venv/lib/python3.10/site-packages/ops/pebble.py", line 1441, in wait_output
    raise ExecError[AnyStr](self._command, exit_code, out_value, err_value)
ops.pebble.ExecError: non-zero exit code 1 executing ['mysqlsh', '--passwords-from-stdin', '--uri', 'relation-43_7d2da19a916f40@mysql-primary.testing.svc.cluster.local.:3306', '--python', '--file', '/tmp/mysqlsh_script.py'], stdout="\x1b[1mPlease provide the password for 'relation-43_7d2da19a916f40@mysql-primary.testing.svc.cluster.local.:3306': \x1b[0m", stderr='Cannot set LC_ALL to locale en_US.UTF-8: No such file or directory\nTraceback (most recent call last):\n  File "<string>", line 11, in <module>\nmysqlsh.Error: Shell Error (51603): ClusterSet.list_routers: Could not connect to PRIMARY of Primary Cluster \'cluster-6d308c0e988834f2cfb622ed306a10d5\'\n'

During handling of the above exception, another exception occurred:

Traceback (most recent call last):
  File "/var/lib/juju/agents/unit-router6-2/charm/src/mysql_shell/__init__.py", line 74, in _run_code
    self._container.run_mysql_shell(
  File "/var/lib/juju/agents/unit-router6-2/charm/lib/charms/tempo_coordinator_k8s/v0/charm_tracing.py", line 735, in wrapped_function
    return callable(*args, **kwargs)  # type: ignore
  File "/var/lib/juju/agents/unit-router6-2/charm/src/container.py", line 212, in run_mysql_shell
    return self._run_command(args, timeout=timeout, input=input)
  File "/var/lib/juju/agents/unit-router6-2/charm/lib/charms/tempo_coordinator_k8s/v0/charm_tracing.py", line 735, in wrapped_function
    return callable(*args, **kwargs)  # type: ignore
  File "/var/lib/juju/agents/unit-router6-2/charm/src/rock.py", line 252, in _run_command
    raise container.CalledProcessError(
container.CalledProcessError: Command '['mysqlsh', '--passwords-from-stdin', '--uri', 'relation-43_7d2da19a916f40@mysql-primary.testing.svc.cluster.local.:3306', '--python', '--file', '/tmp/mysqlsh_script.py']' returned non-zero exit status 1.
unit-router6-2: 01:39:59 ERROR unit.router6/2.juju-log database:44: Uncaught exception while in charm code:
Traceback (most recent call last):
  File "/var/lib/juju/agents/unit-router6-2/charm/src/rock.py", line 250, in _run_command
    output, _ = process.wait_output()
  File "/var/lib/juju/agents/unit-router6-2/charm/venv/lib/python3.10/site-packages/ops/pebble.py", line 1441, in wait_output
    raise ExecError[AnyStr](self._command, exit_code, out_value, err_value)
ops.pebble.ExecError: non-zero exit code 1 executing ['mysqlsh', '--passwords-from-stdin', '--uri', 'relation-43_7d2da19a916f40@mysql-primary.testing.svc.cluster.local.:3306', '--python', '--file', '/tmp/mysqlsh_script.py'], stdout="\x1b[1mPlease provide the password for 'relation-43_7d2da19a916f40@mysql-primary.testing.svc.cluster.local.:3306': \x1b[0m", stderr='Cannot set LC_ALL to locale en_US.UTF-8: No such file or directory\nTraceback (most recent call last):\n  File "<string>", line 11, in <module>\nmysqlsh.Error: Shell Error (51603): ClusterSet.list_routers: Could not connect to PRIMARY of Primary Cluster \'cluster-6d308c0e988834f2cfb622ed306a10d5\'\n'

During handling of the above exception, another exception occurred:

Traceback (most recent call last):
  File "/var/lib/juju/agents/unit-router6-2/charm/src/charm.py", line 454, in <module>
    ops.main.main(KubernetesRouterCharm)
  File "/var/lib/juju/agents/unit-router6-2/charm/venv/lib/python3.10/site-packages/ops/main.py", line 436, in main
    _emit_charm_event(charm, dispatcher.event_name)
  File "/var/lib/juju/agents/unit-router6-2/charm/venv/lib/python3.10/site-packages/ops/main.py", line 144, in _emit_charm_event
    event_to_emit.emit(*args, **kwargs)
  File "/var/lib/juju/agents/unit-router6-2/charm/venv/lib/python3.10/site-packages/ops/framework.py", line 351, in emit
    framework._emit(event)
  File "/var/lib/juju/agents/unit-router6-2/charm/venv/lib/python3.10/site-packages/ops/framework.py", line 853, in _emit
    self._reemit(event_path)
  File "/var/lib/juju/agents/unit-router6-2/charm/venv/lib/python3.10/site-packages/ops/framework.py", line 942, in _reemit
    custom_handler(event)
  File "/var/lib/juju/agents/unit-router6-2/charm/lib/charms/tempo_coordinator_k8s/v0/charm_tracing.py", line 735, in wrapped_function
    return callable(*args, **kwargs)  # type: ignore
  File "/var/lib/juju/agents/unit-router6-2/charm/src/abstract_charm.py", line 375, in reconcile
    self.set_status(event=event)
  File "/var/lib/juju/agents/unit-router6-2/charm/lib/charms/tempo_coordinator_k8s/v0/charm_tracing.py", line 735, in wrapped_function
    return callable(*args, **kwargs)  # type: ignore
  File "/var/lib/juju/agents/unit-router6-2/charm/src/abstract_charm.py", line 232, in set_status
    self.unit.status = self._determine_unit_status(event=event)
  File "/var/lib/juju/agents/unit-router6-2/charm/lib/charms/tempo_coordinator_k8s/v0/charm_tracing.py", line 735, in wrapped_function
    return callable(*args, **kwargs)  # type: ignore
  File "/var/lib/juju/agents/unit-router6-2/charm/src/abstract_charm.py", line 217, in _determine_unit_status
    workload_status = self.get_workload(event=event).status
  File "/var/lib/juju/agents/unit-router6-2/charm/src/workload.py", line 423, in status
    if not self.shell.is_router_in_cluster_set(self._router_id):
  File "/var/lib/juju/agents/unit-router6-2/charm/src/mysql_shell/__init__.py", line 214, in is_router_in_cluster_set
    self._run_code(
  File "/var/lib/juju/agents/unit-router6-2/charm/src/mysql_shell/__init__.py", line 74, in _run_code
    self._container.run_mysql_shell(
  File "/var/lib/juju/agents/unit-router6-2/charm/lib/charms/tempo_coordinator_k8s/v0/charm_tracing.py", line 735, in wrapped_function
    return callable(*args, **kwargs)  # type: ignore
  File "/var/lib/juju/agents/unit-router6-2/charm/src/container.py", line 212, in run_mysql_shell
    return self._run_command(args, timeout=timeout, input=input)
  File "/var/lib/juju/agents/unit-router6-2/charm/lib/charms/tempo_coordinator_k8s/v0/charm_tracing.py", line 735, in wrapped_function
    return callable(*args, **kwargs)  # type: ignore
  File "/var/lib/juju/agents/unit-router6-2/charm/src/rock.py", line 252, in _run_command
    raise container.CalledProcessError(
container.CalledProcessError: Command '['mysqlsh', '--passwords-from-stdin', '--uri', 'relation-43_7d2da19a916f40@mysql-primary.testing.svc.cluster.local.:3306', '--python', '--file', '/tmp/mysqlsh_script.py']' returned non-zero exit status 1.
unit-router6-2: 01:40:00 ERROR juju.worker.uniter.operation hook "database-relation-broken" (via hook dispatching script: dispatch) failed: exit status 1
unit-mysql-1: 01:42:22 ERROR juju.worker.dependency "log-sender" manifold worker returned unexpected error: sending log message: websocket: close 1005 (no status): websocket: close sent

[32mINFO    [0m pytest_operator.plugin:plugin.py:862 Forgetting main...