[32mINFO    [0m pytest_operator.plugin:plugin.py:790 Model status:

Model  Controller          Cloud/Region        Version  SLA          Timestamp
test   microk8s-localhost  microk8s/localhost  3.1.7    unsupported  02:24:03Z

App             Version                  Status   Scale  Charm           Channel      Rev  Address         Exposed  Message
mysql-k8s       8.0.35-0ubuntu0.22.04.1  waiting      3  mysql-k8s                      0  10.152.183.189  no       installing agent
mysql-test-app  0.0.2                    active       1  mysql-test-app  latest/edge   29  10.152.183.195  no       

Unit               Workload     Agent  Address      Ports  Message
mysql-k8s/0*       active       idle   10.1.71.139         
mysql-k8s/1        maintenance  idle   10.1.71.141         offline
mysql-k8s/2        maintenance  idle   10.1.71.140         offline
mysql-test-app/0*  active       idle   10.1.71.142         

[32mINFO    [0m pytest_operator.plugin:plugin.py:796 Juju error logs:

unit-mysql-k8s-0: 01:31:25 ERROR unit.mysql-k8s/0.juju-log Failed to get cluster status for test_cluster
unit-mysql-k8s-0: 01:31:37 ERROR unit.mysql-k8s/0.juju-log Failed to get cluster status for test_cluster
unit-mysql-k8s-0: 01:33:00 ERROR unit.mysql-k8s/0.juju-log Failed to get cluster status for test_cluster
unit-mysql-k8s-0: 01:37:55 ERROR unit.mysql-k8s/0.juju-log Failed to get cluster status for test_cluster
unit-mysql-k8s-2: 01:38:54 ERROR juju.worker.dependency "api-caller" manifold worker returned unexpected error: api connection broken unexpectedly
unit-mysql-k8s-2: 01:38:54 ERROR juju.worker.caasunitterminationworker error while terminating unit: connection is shut down
unit-mysql-k8s-2: 01:39:00 ERROR juju.worker.dependency "api-caller" manifold worker returned unexpected error: [de668a] "unit-mysql-k8s-2" cannot open api: cannot resolve "controller-service.controller-microk8s-localhost.svc.cluster.local": lookup controller-service.controller-microk8s-localhost.svc.cluster.local: i/o timeout
unit-mysql-k8s-2: 01:39:06 ERROR juju.worker.dependency "api-caller" manifold worker returned unexpected error: [de668a] "unit-mysql-k8s-2" cannot open api: cannot resolve "controller-service.controller-microk8s-localhost.svc.cluster.local": lookup controller-service.controller-microk8s-localhost.svc.cluster.local: i/o timeout
unit-mysql-k8s-2: 01:39:13 ERROR juju.worker.dependency "api-caller" manifold worker returned unexpected error: [de668a] "unit-mysql-k8s-2" cannot open api: cannot resolve "controller-service.controller-microk8s-localhost.svc.cluster.local": lookup controller-service.controller-microk8s-localhost.svc.cluster.local: i/o timeout
unit-mysql-k8s-2: 01:39:22 ERROR juju.worker.dependency "api-caller" manifold worker returned unexpected error: [de668a] "unit-mysql-k8s-2" cannot open api: cannot resolve "controller-service.controller-microk8s-localhost.svc.cluster.local": lookup controller-service.controller-microk8s-localhost.svc.cluster.local: i/o timeout
unit-mysql-k8s-2: 01:39:31 ERROR juju.worker.dependency "api-caller" manifold worker returned unexpected error: [de668a] "unit-mysql-k8s-2" cannot open api: try was stopped
unit-mysql-k8s-2: 01:39:41 ERROR juju.worker.dependency "api-caller" manifold worker returned unexpected error: [de668a] "unit-mysql-k8s-2" cannot open api: cannot resolve "controller-service.controller-microk8s-localhost.svc.cluster.local": lookup controller-service.controller-microk8s-localhost.svc.cluster.local: i/o timeout
unit-mysql-k8s-2: 01:39:54 ERROR juju.worker.dependency "api-caller" manifold worker returned unexpected error: [de668a] "unit-mysql-k8s-2" cannot open api: cannot resolve "controller-service.controller-microk8s-localhost.svc.cluster.local": lookup controller-service.controller-microk8s-localhost.svc.cluster.local: i/o timeout
unit-mysql-k8s-2: 01:40:08 ERROR juju.worker.dependency "api-caller" manifold worker returned unexpected error: [de668a] "unit-mysql-k8s-2" cannot open api: cannot resolve "controller-service.controller-microk8s-localhost.svc.cluster.local": lookup controller-service.controller-microk8s-localhost.svc.cluster.local: i/o timeout
unit-mysql-k8s-2: 01:40:44 ERROR unit.mysql-k8s/2.juju-log Failed to get cluster status for test_cluster
unit-mysql-k8s-1: 01:42:53 ERROR unit.mysql-k8s/1.juju-log database-peers:0: Failed to get cluster status for test_cluster
unit-mysql-k8s-1: 01:42:58 ERROR unit.mysql-k8s/1.juju-log database-peers:0: Failed to get cluster status for test_cluster
unit-mysql-k8s-1: 01:43:01 ERROR unit.mysql-k8s/1.juju-log Failed to flush ERROR LOGS logs.
Traceback (most recent call last):
  File "/var/lib/juju/agents/unit-mysql-k8s-1/charm/src/mysql_k8s_helpers.py", line 666, in _run_mysqlsh_script
    stdout, _ = process.wait_output()
  File "/var/lib/juju/agents/unit-mysql-k8s-1/charm/venv/ops/pebble.py", line 1355, in wait_output
    raise ExecError[AnyStr](self._command, exit_code, out_value, err_value)
ops.pebble.ExecError: non-zero exit code 1 executing ['/usr/bin/mysqlsh', '--no-wizard', '--python', '--verbose=1', '-f', '/tmp/script.py', ';', 'rm', '/tmp/script.py'], stdout='', stderr='Cannot set LC_ALL to locale en_US.UTF-8: No such file or directory\nverbose: 2024-01-28T01:43:00Z: Loading startup files...\nverbose: 2024-01-28T01:43:00Z: Loading plugins...\nverbose: 2024-01-28T01:43:00Z: Connecting to MySQL at: serverconfig@mysql-k8s-1.mysql-k8s-endpoints.test.svc.cluster.local\nTraceback (most recent call last):\n  File "<string>", line 1, in <module>\nmysqlsh.DBError: MySQL Error (2003): Shell.connect: Can\'t connect to MySQL server on \'mysql-k8s-1.mysql-k8s-endpoints.test.svc.cluster.local:3306\' (111)\n'

During handling of the above exception, another exception occurred:

Traceback (most recent call last):
  File "/var/lib/juju/agents/unit-mysql-k8s-1/charm/lib/charms/mysql/v0/mysql.py", line 2517, in flush_mysql_logs
    self._run_mysqlsh_script("\n".join(flush_logs_commands))
  File "/var/lib/juju/agents/unit-mysql-k8s-1/charm/src/mysql_k8s_helpers.py", line 669, in _run_mysqlsh_script
    raise MySQLClientError(e.stderr)
charms.mysql.v0.mysql.MySQLClientError: Cannot set LC_ALL to locale en_US.UTF-8: No such file or directory
verbose: 2024-01-28T01:43:00Z: Loading startup files...
verbose: 2024-01-28T01:43:00Z: Loading plugins...
verbose: 2024-01-28T01:43:00Z: Connecting to MySQL at: serverconfig@mysql-k8s-1.mysql-k8s-endpoints.test.svc.cluster.local
Traceback (most recent call last):
  File "<string>", line 1, in <module>
mysqlsh.DBError: MySQL Error (2003): Shell.connect: Can't connect to MySQL server on 'mysql-k8s-1.mysql-k8s-endpoints.test.svc.cluster.local:3306' (111)

unit-mysql-k8s-1: 01:43:01 ERROR unit.mysql-k8s/1.juju-log Failed to flush GENERAL LOGS logs.
Traceback (most recent call last):
  File "/var/lib/juju/agents/unit-mysql-k8s-1/charm/src/mysql_k8s_helpers.py", line 666, in _run_mysqlsh_script
    stdout, _ = process.wait_output()
  File "/var/lib/juju/agents/unit-mysql-k8s-1/charm/venv/ops/pebble.py", line 1355, in wait_output
    raise ExecError[AnyStr](self._command, exit_code, out_value, err_value)
ops.pebble.ExecError: non-zero exit code 1 executing ['/usr/bin/mysqlsh', '--no-wizard', '--python', '--verbose=1', '-f', '/tmp/script.py', ';', 'rm', '/tmp/script.py'], stdout='', stderr='Cannot set LC_ALL to locale en_US.UTF-8: No such file or directory\nverbose: 2024-01-28T01:43:01Z: Loading startup files...\nverbose: 2024-01-28T01:43:01Z: Loading plugins...\nverbose: 2024-01-28T01:43:01Z: Connecting to MySQL at: serverconfig@mysql-k8s-1.mysql-k8s-endpoints.test.svc.cluster.local\nTraceback (most recent call last):\n  File "<string>", line 1, in <module>\nmysqlsh.DBError: MySQL Error (2003): Shell.connect: Can\'t connect to MySQL server on \'mysql-k8s-1.mysql-k8s-endpoints.test.svc.cluster.local:3306\' (111)\n'

During handling of the above exception, another exception occurred:

Traceback (most recent call last):
  File "/var/lib/juju/agents/unit-mysql-k8s-1/charm/lib/charms/mysql/v0/mysql.py", line 2517, in flush_mysql_logs
    self._run_mysqlsh_script("\n".join(flush_logs_commands))
  File "/var/lib/juju/agents/unit-mysql-k8s-1/charm/src/mysql_k8s_helpers.py", line 669, in _run_mysqlsh_script
    raise MySQLClientError(e.stderr)
charms.mysql.v0.mysql.MySQLClientError: Cannot set LC_ALL to locale en_US.UTF-8: No such file or directory
verbose: 2024-01-28T01:43:01Z: Loading startup files...
verbose: 2024-01-28T01:43:01Z: Loading plugins...
verbose: 2024-01-28T01:43:01Z: Connecting to MySQL at: serverconfig@mysql-k8s-1.mysql-k8s-endpoints.test.svc.cluster.local
Traceback (most recent call last):
  File "<string>", line 1, in <module>
mysqlsh.DBError: MySQL Error (2003): Shell.connect: Can't connect to MySQL server on 'mysql-k8s-1.mysql-k8s-endpoints.test.svc.cluster.local:3306' (111)

unit-mysql-k8s-1: 01:43:01 ERROR unit.mysql-k8s/1.juju-log Failed to flush SLOW LOGS logs.
Traceback (most recent call last):
  File "/var/lib/juju/agents/unit-mysql-k8s-1/charm/src/mysql_k8s_helpers.py", line 666, in _run_mysqlsh_script
    stdout, _ = process.wait_output()
  File "/var/lib/juju/agents/unit-mysql-k8s-1/charm/venv/ops/pebble.py", line 1355, in wait_output
    raise ExecError[AnyStr](self._command, exit_code, out_value, err_value)
ops.pebble.ExecError: non-zero exit code 1 executing ['/usr/bin/mysqlsh', '--no-wizard', '--python', '--verbose=1', '-f', '/tmp/script.py', ';', 'rm', '/tmp/script.py'], stdout='', stderr='Cannot set LC_ALL to locale en_US.UTF-8: No such file or directory\nverbose: 2024-01-28T01:43:01Z: Loading startup files...\nverbose: 2024-01-28T01:43:01Z: Loading plugins...\nverbose: 2024-01-28T01:43:01Z: Connecting to MySQL at: serverconfig@mysql-k8s-1.mysql-k8s-endpoints.test.svc.cluster.local\nTraceback (most recent call last):\n  File "<string>", line 1, in <module>\nmysqlsh.DBError: MySQL Error (2003): Shell.connect: Can\'t connect to MySQL server on \'mysql-k8s-1.mysql-k8s-endpoints.test.svc.cluster.local:3306\' (111)\n'

During handling of the above exception, another exception occurred:

Traceback (most recent call last):
  File "/var/lib/juju/agents/unit-mysql-k8s-1/charm/lib/charms/mysql/v0/mysql.py", line 2517, in flush_mysql_logs
    self._run_mysqlsh_script("\n".join(flush_logs_commands))
  File "/var/lib/juju/agents/unit-mysql-k8s-1/charm/src/mysql_k8s_helpers.py", line 669, in _run_mysqlsh_script
    raise MySQLClientError(e.stderr)
charms.mysql.v0.mysql.MySQLClientError: Cannot set LC_ALL to locale en_US.UTF-8: No such file or directory
verbose: 2024-01-28T01:43:01Z: Loading startup files...
verbose: 2024-01-28T01:43:01Z: Loading plugins...
verbose: 2024-01-28T01:43:01Z: Connecting to MySQL at: serverconfig@mysql-k8s-1.mysql-k8s-endpoints.test.svc.cluster.local
Traceback (most recent call last):
  File "<string>", line 1, in <module>
mysqlsh.DBError: MySQL Error (2003): Shell.connect: Can't connect to MySQL server on 'mysql-k8s-1.mysql-k8s-endpoints.test.svc.cluster.local:3306' (111)

unit-mysql-k8s-2: 01:44:01 ERROR unit.mysql-k8s/2.juju-log Failed to flush ERROR LOGS logs.
Traceback (most recent call last):
  File "/var/lib/juju/agents/unit-mysql-k8s-2/charm/src/mysql_k8s_helpers.py", line 666, in _run_mysqlsh_script
    stdout, _ = process.wait_output()
  File "/var/lib/juju/agents/unit-mysql-k8s-2/charm/venv/ops/pebble.py", line 1355, in wait_output
    raise ExecError[AnyStr](self._command, exit_code, out_value, err_value)
ops.pebble.ExecError: non-zero exit code 1 executing ['/usr/bin/mysqlsh', '--no-wizard', '--python', '--verbose=1', '-f', '/tmp/script.py', ';', 'rm', '/tmp/script.py'], stdout='', stderr='Cannot set LC_ALL to locale en_US.UTF-8: No such file or directory\nverbose: 2024-01-28T01:44:01Z: Loading startup files...\nverbose: 2024-01-28T01:44:01Z: Loading plugins...\nverbose: 2024-01-28T01:44:01Z: Connecting to MySQL at: serverconfig@mysql-k8s-2.mysql-k8s-endpoints.test.svc.cluster.local\nTraceback (most recent call last):\n  File "<string>", line 1, in <module>\nmysqlsh.DBError: MySQL Error (2003): Shell.connect: Can\'t connect to MySQL server on \'mysql-k8s-2.mysql-k8s-endpoints.test.svc.cluster.local:3306\' (111)\n'

During handling of the above exception, another exception occurred:

Traceback (most recent call last):
  File "/var/lib/juju/agents/unit-mysql-k8s-2/charm/lib/charms/mysql/v0/mysql.py", line 2517, in flush_mysql_logs
    self._run_mysqlsh_script("\n".join(flush_logs_commands))
  File "/var/lib/juju/agents/unit-mysql-k8s-2/charm/src/mysql_k8s_helpers.py", line 669, in _run_mysqlsh_script
    raise MySQLClientError(e.stderr)
charms.mysql.v0.mysql.MySQLClientError: Cannot set LC_ALL to locale en_US.UTF-8: No such file or directory
verbose: 2024-01-28T01:44:01Z: Loading startup files...
verbose: 2024-01-28T01:44:01Z: Loading plugins...
verbose: 2024-01-28T01:44:01Z: Connecting to MySQL at: serverconfig@mysql-k8s-2.mysql-k8s-endpoints.test.svc.cluster.local
Traceback (most recent call last):
  File "<string>", line 1, in <module>
mysqlsh.DBError: MySQL Error (2003): Shell.connect: Can't connect to MySQL server on 'mysql-k8s-2.mysql-k8s-endpoints.test.svc.cluster.local:3306' (111)

unit-mysql-k8s-1: 01:44:01 ERROR unit.mysql-k8s/1.juju-log Failed to flush ERROR LOGS logs.
Traceback (most recent call last):
  File "/var/lib/juju/agents/unit-mysql-k8s-1/charm/src/mysql_k8s_helpers.py", line 666, in _run_mysqlsh_script
    stdout, _ = process.wait_output()
  File "/var/lib/juju/agents/unit-mysql-k8s-1/charm/venv/ops/pebble.py", line 1355, in wait_output
    raise ExecError[AnyStr](self._command, exit_code, out_value, err_value)
ops.pebble.ExecError: non-zero exit code 1 executing ['/usr/bin/mysqlsh', '--no-wizard', '--python', '--verbose=1', '-f', '/tmp/script.py', ';', 'rm', '/tmp/script.py'], stdout='', stderr='Cannot set LC_ALL to locale en_US.UTF-8: No such file or directory\nverbose: 2024-01-28T01:44:01Z: Loading startup files...\nverbose: 2024-01-28T01:44:01Z: Loading plugins...\nverbose: 2024-01-28T01:44:01Z: Connecting to MySQL at: serverconfig@mysql-k8s-1.mysql-k8s-endpoints.test.svc.cluster.local\nTraceback (most recent call last):\n  File "<string>", line 1, in <module>\nmysqlsh.DBError: MySQL Error (2003): Shell.connect: Can\'t connect to MySQL server on \'mysql-k8s-1.mysql-k8s-endpoints.test.svc.cluster.local:3306\' (111)\n'

During handling of the above exception, another exception occurred:

Traceback (most recent call last):
  File "/var/lib/juju/agents/unit-mysql-k8s-1/charm/lib/charms/mysql/v0/mysql.py", line 2517, in flush_mysql_logs
    self._run_mysqlsh_script("\n".join(flush_logs_commands))
  File "/var/lib/juju/agents/unit-mysql-k8s-1/charm/src/mysql_k8s_helpers.py", line 669, in _run_mysqlsh_script
    raise MySQLClientError(e.stderr)
charms.mysql.v0.mysql.MySQLClientError: Cannot set LC_ALL to locale en_US.UTF-8: No such file or directory
verbose: 2024-01-28T01:44:01Z: Loading startup files...
verbose: 2024-01-28T01:44:01Z: Loading plugins...
verbose: 2024-01-28T01:44:01Z: Connecting to MySQL at: serverconfig@mysql-k8s-1.mysql-k8s-endpoints.test.svc.cluster.local
Traceback (most recent call last):
  File "<string>", line 1, in <module>
mysqlsh.DBError: MySQL Error (2003): Shell.connect: Can't connect to MySQL server on 'mysql-k8s-1.mysql-k8s-endpoints.test.svc.cluster.local:3306' (111)

unit-mysql-k8s-2: 01:44:01 ERROR unit.mysql-k8s/2.juju-log Failed to flush GENERAL LOGS logs.
Traceback (most recent call last):
  File "/var/lib/juju/agents/unit-mysql-k8s-2/charm/src/mysql_k8s_helpers.py", line 666, in _run_mysqlsh_script
    stdout, _ = process.wait_output()
  File "/var/lib/juju/agents/unit-mysql-k8s-2/charm/venv/ops/pebble.py", line 1355, in wait_output
    raise ExecError[AnyStr](self._command, exit_code, out_value, err_value)
ops.pebble.ExecError: non-zero exit code 1 executing ['/usr/bin/mysqlsh', '--no-wizard', '--python', '--verbose=1', '-f', '/tmp/script.py', ';', 'rm', '/tmp/script.py'], stdout='', stderr='Cannot set LC_ALL to locale en_US.UTF-8: No such file or directory\nverbose: 2024-01-28T01:44:01Z: Loading startup files...\nverbose: 2024-01-28T01:44:01Z: Loading plugins...\nverbose: 2024-01-28T01:44:01Z: Connecting to MySQL at: serverconfig@mysql-k8s-2.mysql-k8s-endpoints.test.svc.cluster.local\nTraceback (most recent call last):\n  File "<string>", line 1, in <module>\nmysqlsh.DBError: MySQL Error (2003): Shell.connect: Can\'t connect to MySQL server on \'mysql-k8s-2.mysql-k8s-endpoints.test.svc.cluster.local:3306\' (111)\n'

During handling of the above exception, another exception occurred:

Traceback (most recent call last):
  File "/var/lib/juju/agents/unit-mysql-k8s-2/charm/lib/charms/mysql/v0/mysql.py", line 2517, in flush_mysql_logs
    self._run_mysqlsh_script("\n".join(flush_logs_commands))
  File "/var/lib/juju/agents/unit-mysql-k8s-2/charm/src/mysql_k8s_helpers.py", line 669, in _run_mysqlsh_script
    raise MySQLClientError(e.stderr)
charms.mysql.v0.mysql.MySQLClientError: Cannot set LC_ALL to locale en_US.UTF-8: No such file or directory
verbose: 2024-01-28T01:44:01Z: Loading startup files...
verbose: 2024-01-28T01:44:01Z: Loading plugins...
verbose: 2024-01-28T01:44:01Z: Connecting to MySQL at: serverconfig@mysql-k8s-2.mysql-k8s-endpoints.test.svc.cluster.local
Traceback (most recent call last):
  File "<string>", line 1, in <module>
mysqlsh.DBError: MySQL Error (2003): Shell.connect: Can't connect to MySQL server on 'mysql-k8s-2.mysql-k8s-endpoints.test.svc.cluster.local:3306' (111)

unit-mysql-k8s-2: 01:44:02 ERROR unit.mysql-k8s/2.juju-log Failed to flush SLOW LOGS logs.
Traceback (most recent call last):
  File "/var/lib/juju/agents/unit-mysql-k8s-2/charm/src/mysql_k8s_helpers.py", line 666, in _run_mysqlsh_script
    stdout, _ = process.wait_output()
  File "/var/lib/juju/agents/unit-mysql-k8s-2/charm/venv/ops/pebble.py", line 1355, in wait_output
    raise ExecError[AnyStr](self._command, exit_code, out_value, err_value)
ops.pebble.ExecError: non-zero exit code 1 executing ['/usr/bin/mysqlsh', '--no-wizard', '--python', '--verbose=1', '-f', '/tmp/script.py', ';', 'rm', '/tmp/script.py'], stdout='', stderr='Cannot set LC_ALL to locale en_US.UTF-8: No such file or directory\nverbose: 2024-01-28T01:44:02Z: Loading startup files...\nverbose: 2024-01-28T01:44:02Z: Loading plugins...\nverbose: 2024-01-28T01:44:02Z: Connecting to MySQL at: serverconfig@mysql-k8s-2.mysql-k8s-endpoints.test.svc.cluster.local\nTraceback (most recent call last):\n  File "<string>", line 1, in <module>\nmysqlsh.DBError: MySQL Error (2003): Shell.connect: Can\'t connect to MySQL server on \'mysql-k8s-2.mysql-k8s-endpoints.test.svc.cluster.local:3306\' (111)\n'

During handling of the above exception, another exception occurred:

Traceback (most recent call last):
  File "/var/lib/juju/agents/unit-mysql-k8s-2/charm/lib/charms/mysql/v0/mysql.py", line 2517, in flush_mysql_logs
    self._run_mysqlsh_script("\n".join(flush_logs_commands))
  File "/var/lib/juju/agents/unit-mysql-k8s-2/charm/src/mysql_k8s_helpers.py", line 669, in _run_mysqlsh_script
    raise MySQLClientError(e.stderr)
charms.mysql.v0.mysql.MySQLClientError: Cannot set LC_ALL to locale en_US.UTF-8: No such file or directory
verbose: 2024-01-28T01:44:02Z: Loading startup files...
verbose: 2024-01-28T01:44:02Z: Loading plugins...
verbose: 2024-01-28T01:44:02Z: Connecting to MySQL at: serverconfig@mysql-k8s-2.mysql-k8s-endpoints.test.svc.cluster.local
Traceback (most recent call last):
  File "<string>", line 1, in <module>
mysqlsh.DBError: MySQL Error (2003): Shell.connect: Can't connect to MySQL server on 'mysql-k8s-2.mysql-k8s-endpoints.test.svc.cluster.local:3306' (111)

unit-mysql-k8s-2: 01:45:04 ERROR unit.mysql-k8s/2.juju-log Failed to get cluster status for test_cluster
unit-mysql-k8s-1: 01:45:07 ERROR unit.mysql-k8s/1.juju-log Failed to get cluster status for test_cluster
unit-mysql-k8s-2: 01:45:09 ERROR unit.mysql-k8s/2.juju-log database-peers:0: Failed to get cluster status for test_cluster
unit-mysql-k8s-2: 01:46:08 ERROR unit.mysql-k8s/2.juju-log Failed to get cluster status for test_cluster
unit-mysql-k8s-1: 01:46:19 ERROR unit.mysql-k8s/1.juju-log Failed to get cluster status for test_cluster
unit-mysql-k8s-2: 01:46:56 ERROR unit.mysql-k8s/2.juju-log Failed to get cluster status for test_cluster
unit-mysql-k8s-1: 01:47:21 ERROR unit.mysql-k8s/1.juju-log Failed to get cluster status for test_cluster
unit-mysql-k8s-2: 01:47:45 ERROR unit.mysql-k8s/2.juju-log Failed to get cluster status for test_cluster
unit-mysql-k8s-1: 01:48:11 ERROR unit.mysql-k8s/1.juju-log Failed to get cluster status for test_cluster
unit-mysql-k8s-2: 01:48:40 ERROR unit.mysql-k8s/2.juju-log Failed to get cluster status for test_cluster
unit-mysql-k8s-1: 01:49:15 ERROR unit.mysql-k8s/1.juju-log Failed to get cluster status for test_cluster
unit-mysql-k8s-2: 01:49:34 ERROR unit.mysql-k8s/2.juju-log Failed to get cluster status for test_cluster
unit-mysql-k8s-1: 01:50:26 ERROR unit.mysql-k8s/1.juju-log Failed to get cluster status for test_cluster
unit-mysql-k8s-2: 01:50:36 ERROR unit.mysql-k8s/2.juju-log Failed to get cluster status for test_cluster
unit-mysql-k8s-2: 01:51:28 ERROR unit.mysql-k8s/2.juju-log Failed to get cluster status for test_cluster
unit-mysql-k8s-1: 01:51:35 ERROR unit.mysql-k8s/1.juju-log Failed to get cluster status for test_cluster
unit-mysql-k8s-2: 01:52:21 ERROR unit.mysql-k8s/2.juju-log Failed to get cluster status for test_cluster
unit-mysql-k8s-1: 01:52:30 ERROR unit.mysql-k8s/1.juju-log Failed to get cluster status for test_cluster
unit-mysql-k8s-2: 01:53:22 ERROR unit.mysql-k8s/2.juju-log Failed to get cluster status for test_cluster
unit-mysql-k8s-1: 01:53:40 ERROR unit.mysql-k8s/1.juju-log Failed to get cluster status for test_cluster
unit-mysql-k8s-2: 01:54:21 ERROR unit.mysql-k8s/2.juju-log Failed to get cluster status for test_cluster
unit-mysql-k8s-1: 01:54:38 ERROR unit.mysql-k8s/1.juju-log Failed to get cluster status for test_cluster
unit-mysql-k8s-2: 01:55:20 ERROR unit.mysql-k8s/2.juju-log Failed to get cluster status for test_cluster
unit-mysql-k8s-1: 01:55:47 ERROR unit.mysql-k8s/1.juju-log Failed to get cluster status for test_cluster
unit-mysql-k8s-2: 01:56:17 ERROR unit.mysql-k8s/2.juju-log Failed to get cluster status for test_cluster
unit-mysql-k8s-1: 01:56:52 ERROR unit.mysql-k8s/1.juju-log Failed to get cluster status for test_cluster
unit-mysql-k8s-2: 01:57:27 ERROR unit.mysql-k8s/2.juju-log Failed to get cluster status for test_cluster
unit-mysql-k8s-1: 01:57:59 ERROR unit.mysql-k8s/1.juju-log Failed to get cluster status for test_cluster
unit-mysql-k8s-2: 01:58:38 ERROR unit.mysql-k8s/2.juju-log Failed to get cluster status for test_cluster
unit-mysql-k8s-1: 01:58:49 ERROR unit.mysql-k8s/1.juju-log Failed to get cluster status for test_cluster
unit-mysql-k8s-2: 01:59:42 ERROR unit.mysql-k8s/2.juju-log Failed to get cluster status for test_cluster
unit-mysql-k8s-1: 01:59:43 ERROR unit.mysql-k8s/1.juju-log Failed to get cluster status for test_cluster
unit-mysql-k8s-2: 02:00:44 ERROR unit.mysql-k8s/2.juju-log Failed to get cluster status for test_cluster
unit-mysql-k8s-1: 02:00:45 ERROR unit.mysql-k8s/1.juju-log Failed to get cluster status for test_cluster
unit-mysql-k8s-1: 02:01:45 ERROR unit.mysql-k8s/1.juju-log Failed to get cluster status for test_cluster
unit-mysql-k8s-2: 02:01:49 ERROR unit.mysql-k8s/2.juju-log Failed to get cluster status for test_cluster
unit-mysql-k8s-2: 02:02:41 ERROR unit.mysql-k8s/2.juju-log Failed to get cluster status for test_cluster
unit-mysql-k8s-1: 02:02:41 ERROR unit.mysql-k8s/1.juju-log Failed to get cluster status for test_cluster
unit-mysql-k8s-2: 02:03:32 ERROR unit.mysql-k8s/2.juju-log Failed to get cluster status for test_cluster
unit-mysql-k8s-1: 02:03:45 ERROR unit.mysql-k8s/1.juju-log Failed to get cluster status for test_cluster
unit-mysql-k8s-1: 02:04:42 ERROR unit.mysql-k8s/1.juju-log Failed to get cluster status for test_cluster
unit-mysql-k8s-2: 02:04:43 ERROR unit.mysql-k8s/2.juju-log Failed to get cluster status for test_cluster
unit-mysql-k8s-1: 02:05:42 ERROR unit.mysql-k8s/1.juju-log Failed to get cluster status for test_cluster
unit-mysql-k8s-2: 02:05:52 ERROR unit.mysql-k8s/2.juju-log Failed to get cluster status for test_cluster
unit-mysql-k8s-2: 02:06:46 ERROR unit.mysql-k8s/2.juju-log Failed to get cluster status for test_cluster
unit-mysql-k8s-1: 02:06:49 ERROR unit.mysql-k8s/1.juju-log Failed to get cluster status for test_cluster
unit-mysql-k8s-2: 02:07:38 ERROR unit.mysql-k8s/2.juju-log Failed to get cluster status for test_cluster
unit-mysql-k8s-1: 02:07:49 ERROR unit.mysql-k8s/1.juju-log Failed to get cluster status for test_cluster
unit-mysql-k8s-1: 02:08:39 ERROR unit.mysql-k8s/1.juju-log Failed to get cluster status for test_cluster
unit-mysql-k8s-2: 02:08:40 ERROR unit.mysql-k8s/2.juju-log Failed to get cluster status for test_cluster
unit-mysql-k8s-2: 02:09:41 ERROR unit.mysql-k8s/2.juju-log Failed to get cluster status for test_cluster
unit-mysql-k8s-1: 02:09:42 ERROR unit.mysql-k8s/1.juju-log Failed to get cluster status for test_cluster
unit-mysql-k8s-2: 02:10:35 ERROR unit.mysql-k8s/2.juju-log Failed to get cluster status for test_cluster
unit-mysql-k8s-1: 02:10:53 ERROR unit.mysql-k8s/1.juju-log Failed to get cluster status for test_cluster
unit-mysql-k8s-2: 02:11:45 ERROR unit.mysql-k8s/2.juju-log Failed to get cluster status for test_cluster
unit-mysql-k8s-1: 02:12:00 ERROR unit.mysql-k8s/1.juju-log Failed to get cluster status for test_cluster
unit-mysql-k8s-2: 02:12:54 ERROR unit.mysql-k8s/2.juju-log Failed to get cluster status for test_cluster
unit-mysql-k8s-1: 02:13:02 ERROR unit.mysql-k8s/1.juju-log Failed to get cluster status for test_cluster
unit-mysql-k8s-2: 02:13:49 ERROR unit.mysql-k8s/2.juju-log Failed to get cluster status for test_cluster
unit-mysql-k8s-1: 02:13:58 ERROR unit.mysql-k8s/1.juju-log Failed to get cluster status for test_cluster
unit-mysql-k8s-2: 02:14:48 ERROR unit.mysql-k8s/2.juju-log Failed to get cluster status for test_cluster
unit-mysql-k8s-1: 02:15:02 ERROR unit.mysql-k8s/1.juju-log Failed to get cluster status for test_cluster
unit-mysql-k8s-2: 02:15:52 ERROR unit.mysql-k8s/2.juju-log Failed to get cluster status for test_cluster
unit-mysql-k8s-1: 02:16:07 ERROR unit.mysql-k8s/1.juju-log Failed to get cluster status for test_cluster
unit-mysql-k8s-2: 02:16:55 ERROR unit.mysql-k8s/2.juju-log Failed to get cluster status for test_cluster
unit-mysql-k8s-1: 02:16:56 ERROR unit.mysql-k8s/1.juju-log Failed to get cluster status for test_cluster
unit-mysql-k8s-2: 02:17:49 ERROR unit.mysql-k8s/2.juju-log Failed to get cluster status for test_cluster
unit-mysql-k8s-1: 02:17:55 ERROR unit.mysql-k8s/1.juju-log Failed to get cluster status for test_cluster
unit-mysql-k8s-2: 02:18:39 ERROR unit.mysql-k8s/2.juju-log Failed to get cluster status for test_cluster
unit-mysql-k8s-1: 02:18:49 ERROR unit.mysql-k8s/1.juju-log Failed to get cluster status for test_cluster
unit-mysql-k8s-2: 02:19:48 ERROR unit.mysql-k8s/2.juju-log Failed to get cluster status for test_cluster
unit-mysql-k8s-1: 02:19:53 ERROR unit.mysql-k8s/1.juju-log Failed to get cluster status for test_cluster
unit-mysql-k8s-2: 02:20:45 ERROR unit.mysql-k8s/2.juju-log Failed to get cluster status for test_cluster
unit-mysql-k8s-1: 02:21:05 ERROR unit.mysql-k8s/1.juju-log Failed to get cluster status for test_cluster
unit-mysql-k8s-2: 02:21:39 ERROR unit.mysql-k8s/2.juju-log Failed to get cluster status for test_cluster
unit-mysql-k8s-1: 02:22:07 ERROR unit.mysql-k8s/1.juju-log Failed to get cluster status for test_cluster
unit-mysql-k8s-2: 02:22:46 ERROR unit.mysql-k8s/2.juju-log Failed to get cluster status for test_cluster
unit-mysql-k8s-1: 02:23:03 ERROR unit.mysql-k8s/1.juju-log Failed to get cluster status for test_cluster
unit-mysql-k8s-2: 02:23:52 ERROR unit.mysql-k8s/2.juju-log Failed to get cluster status for test_cluster

[32mINFO    [0m pytest_operator.plugin:plugin.py:862 Forgetting main...
[1m[31mERROR   [0m websockets.client:protocol.py:1015 data transfer failed
Traceback (most recent call last):
  File "/home/runner/work/mysql-k8s-operator/mysql-k8s-operator/.tox/integration/lib/python3.10/site-packages/websockets/legacy/protocol.py", line 959, in transfer_data
    message = await self.read_message()
  File "/home/runner/work/mysql-k8s-operator/mysql-k8s-operator/.tox/integration/lib/python3.10/site-packages/websockets/legacy/protocol.py", line 1029, in read_message
    frame = await self.read_data_frame(max_size=self.max_size)
  File "/home/runner/work/mysql-k8s-operator/mysql-k8s-operator/.tox/integration/lib/python3.10/site-packages/websockets/legacy/protocol.py", line 1104, in read_data_frame
    frame = await self.read_frame(max_size)
  File "/home/runner/work/mysql-k8s-operator/mysql-k8s-operator/.tox/integration/lib/python3.10/site-packages/websockets/legacy/protocol.py", line 1161, in read_frame
    frame = await Frame.read(
  File "/home/runner/work/mysql-k8s-operator/mysql-k8s-operator/.tox/integration/lib/python3.10/site-packages/websockets/legacy/framing.py", line 68, in read
    data = await reader(2)
  File "/usr/lib/python3.10/asyncio/streams.py", line 708, in readexactly
    await self._wait_for_data('readexactly')
  File "/usr/lib/python3.10/asyncio/streams.py", line 501, in _wait_for_data
    await self._waiter
  File "/usr/lib/python3.10/asyncio/selector_events.py", line 924, in write
    n = self._sock.send(data)
OSError: [Errno 9] Bad file descriptor